Workbook

Sheet MSFT
A1: Price,Close,High,Low,Open,Volume
A2: Ticker,MSFT,MSFT,MSFT,MSFT,MSFT
A3: Date,,,,,
A4: 1986-03-13,0.05925342068076134,0.0618991081671409,0.05396326266094622,0.05396326266094622,1031788800
A5: 1986-03-14,0.061369478702545166,0.06242811869351785,0.05925341567344097,0.05925341567344097,308160000
A6: 1986-03-17,0.06242809444665909,0.0629571099984673,0.0613694548668584,0.0613694548668584,133171200
A7: 1986-03-18,0.06084045022726059,0.0629571212903192,0.060311434580569284,0.0624281056436279,67766400
A8: 1986-03-19,0.059782400727272034,0.06136944718401425,0.05925338524169129,0.06084043169843351,47894400
A9: 1986-03-20,0.058195389807224274,0.059782437233088265,0.05766637399860294,0.059782437233088265,58435200
A10: 1986-03-21,0.05660834535956383,0.05925342454182989,0.0555503136866574,0.058195392868923466,59990400
A11: 1986-03-24,0.055021267384290695,0.056608314014884226,0.05449225184075952,0.056608314014884226,65289600
A12: 1986-03-25,0.05607929825782776,0.05607929825782775,0.054492251633277006,0.05502126717479392,32083200
... A10120: 2026-05-08,415.1199951171875,418.6300048828125,414.0,417.3900146484375,33304300

Sheet MSFT PQ
A1: Date | B1: Close | C1: High | D1: Low | E1: Open
A2: 44200 | B2: 208.40652 | C2: 213,4900752334204 | D2: 205.64934 | E2: 213.04012
A3: 44201 | B3: 208.60757 | C3: 209,2011442852732 | D3: 206.5014 | E3: 207.99487
A4: 44202 | B4: 203.19855 | C4: 207,25773679566413 | D4: 202.90177 | E4: 203.12196
A5: 44203 | B5: 208.9809 | C5: 209,98612108796203 | D5: 204.59623 | E5: 204.91214
A6: 44204 | B6: 210.25423 | C6: 211,17329358978736 | D6: 207.77468 | E6: 209.35431
A7: 44207 | B7: 208.21504 | C7: 209,5744837947097 | D7: 207.48744 | E7: 209.15325
A8: 44208 | B8: 205.76424 | C8: 207,84170898199775 | D8: 204.22291 | E8: 207.26729
A9: 44209 | B9: 207.11411 | C9: 207,51619243191996 | D9: 204.80688 | E9: 204.89305
A10: 44210 | B10: 203.9357 | C10: 208,1863566093762 | D10: 203.66764 | E10: 206.70245
A11: 44211 | B11: 203.58147 | C11: 205,36214696231852 | D11: 202.98791 | E11: 204.41438
A12: 44215 | B12: 207.20987 | C12: 207,72683453458131 | D12: 203.56235 | E12: 204.63458
A13: 44216 | B13: 214.77293 | C13: 216,16109525037086 | D13: 208.02358 | E13: 208.4161
... A1344: 46150 | B1344: 415.12 | C1344: 418,6300048828125 | D1344: 414 | E1344: 417.39001

Sheet SP500
A1: Price,Close,High,Low,Open,Volume
A2: Ticker,^GSPC,^GSPC,^GSPC,^GSPC,^GSPC
A3: Date,,,,,
A4: 1927-12-30,17.65999984741211,17.65999984741211,17.65999984741211,17.65999984741211,0
A5: 1928-01-03,17.760000228881836,17.760000228881836,17.760000228881836,17.760000228881836,0
A6: 1928-01-04,17.719999313354492,17.719999313354492,17.719999313354492,17.719999313354492,0
A7: 1928-01-05,17.549999237060547,17.549999237060547,17.549999237060547,17.549999237060547,0
A8: 1928-01-06,17.65999984741211,17.65999984741211,17.65999984741211,17.65999984741211,0
A9: 1928-01-09,17.5,17.5,17.5,17.5,0
A10: 1928-01-10,17.3700008392334,17.3700008392334,17.3700008392334,17.3700008392334,0
A11: 1928-01-11,17.350000381469727,17.350000381469727,17.350000381469727,17.350000381469727,0
A12: 1928-01-12,17.469999313354492,17.469999313354492,17.469999313354492,17.469999313354492,0
... A24708: 2026-05-08,7398.93017578125,7401.5,7362.97021484375,7362.97021484375,5302740000

Sheet SP500 PQ
A1: Date | B1: Close | C1: High | D1: Low | E1: Open | F1: Volume
A2: 44200 | B2: 3700.6499 | C2: 3769.99 | D2: 3662.71 | E2: 3764.6101 | F2: 5015000000
A3: 44201 | B3: 3726.8601 | C3: 3737.8301 | D3: 3695.0701 | E3: 3698.02 | F3: 4591020000
A4: 44202 | B4: 3748.1399 | C4: 3783.04 | D4: 3705.3401 | E4: 3712.2 | F4: 6064110000
A5: 44203 | B5: 3803.79 | C5: 3811.55 | D5: 3764.71 | E5: 3764.71 | F5: 5099160000
A6: 44204 | B6: 3824.6799 | C6: 3826.6899 | D6: 3783.6001 | E6: 3815.05 | F6: 4773040000
A7: 44207 | B7: 3799.6101 | C7: 3817.8601 | D7: 3789.02 | E7: 3803.1399 | F7: 4465430000
A8: 44208 | B8: 3801.1899 | C8: 3810.78 | D8: 3776.51 | E8: 3801.6201 | F8: 4994950000
A9: 44209 | B9: 3809.8401 | C9: 3820.96 | D9: 3791.5 | E9: 3802.23 | F9: 4602510000
A10: 44210 | B10: 3795.54 | C10: 3823.6001 | D10: 3792.8601 | E10: 3814.98 | F10: 5198480000
A11: 44211 | B11: 3768.25 | C11: 3788.73 | D11: 3749.6201 | E11: 3788.73 | F11: 5369820000
A12: 44215 | B12: 3798.9099 | C12: 3804.53 | D12: 3780.3701 | E12: 3781.8799 | F12: 5014440000
A13: 44216 | B13: 3851.8501 | C13: 3859.75 | D13: 3816.22 | E13: 3816.22 | F13: 4566190000
... A1344: 46150 | B1344: 7398.9302 | C1344: 7401.5 | D1344: 7362.9702 | E1344: 7362.9702 | F1344: 5302740000

Sheet Verifica date
A1: Date | B1: Date.1 | C1: Diff. date
A2: 44200 | B2: 44200 | C2: 0 | E2: N. osservazioni: | F2: =COUNTA(Merge[Diff. date]) -> 1343
A3: 44201 | B3: 44201 | C3: 0 | E3: N. di 0 | F3: =COUNTIF(Merge[Diff. date],0) -> 1343
A4: 44202 | B4: 44202 | C4: 0 | E4: VERIFICA CORRISPONDENZA: | F4: =F2-F3 -> 0
A5: 44203 | B5: 44203 | C5: 0
A6: 44204 | B6: 44204 | C6: 0 | E6: N. giorni dell'anno | F6: 365
A7: 44207 | B7: 44207 | C7: 0 | E7: N. weekend annuali: | F7: =52*2 -> 104
A8: 44208 | B8: 44208 | C8: 0 | E8: N. di osservazioni attese per anno | F8: =F6-F7 -> 261
A9: 44209 | B9: 44209 | C9: 0 | E9: N. di osservazioni per anno (approssimativo): | F9: =COUNTA(Merge[Date])/5 -> 268.6
A10: 44210 | B10: 44210 | C10: 0
A11: 44211 | B11: 44211 | C11: 0 | E11: CONCLUSIONE
A12: 44215 | B12: 44215 | C12: 0 | E12: Utilizzando Power Query sono state abbinate le date relative ai 5 anni precedenti alla data odierna includendo, per convenzione, anche quelli del primo periodo dell'anno.
A13: 44216 | B13: 44216 | C13: 0 | E13: Sempre con Power Query è stata creata la colonna "Diff. Date" che esprime la differenza tra le date relative a ciascun titolo al fine di verificarne la corrispondenza (diff. = 0)
A14: 44217 | B14: 44217 | C14: 0 | E14: La verifica di tutte le osservazioni è stata effettuata contando il numero di osservazioni e il numero di zeri presenti nella colonna.
A15: 44218 | B15: 44218 | C15: 0
A16: 44221 | B16: 44221 | C16: 0 | E16: Considerando che l'anno attuale è ancora in corso ed il numero di weekend presenti in ogni anno (per semplicità non calcoliamo i festivi in quanto poco
A17: 44222 | B17: 44222 | C17: 0 | E17: numerosi rispetto al numero di weekend) possiamo concludere approssimativamente che 268,6 sia un valore accettabile per concludere che i datasets
A18: 44223 | B18: 44223 | C18: 0 | E18: non soffranon di dati mancanti
A19: 44224 | B19: 44224 | C19: 0
A20: 44225 | B20: 44225 | C20: 0
A21: 44228 | B21: 44228 | C21: 0
A22: 44229 | B22: 44229 | C22: 0
A23: 44230 | B23: 44230 | C23: 0
A24: 44231 | B24: 44231 | C24: 0
A25: 44232 | B25: 44232 | C25: 0
A26: 44235 | B26: 44235 | C26: 0
A27: 44236 | B27: 44236 | C27: 0
A28: 44237 | B28: 44237 | C28: 0
A29: 44238 | B29: 44238 | C29: 0
A30: 44239 | B30: 44239 | C30: 0
... A1344: 46150 | B1344: 46150 | C1344: 0

Sheet Rend. GG MSFT
A1: RENDIMENTI GIORNALIERI DI MSFT
A3: Date | B3: Close | C3: Rendimenti giornalieri MSFT | F3: Statistiche rendimenti gg MSFT
A4: 44200 | B4: 208.40652 | C4: 0
A5: 44201 | B5: 208.60757 | C5: =(B5-B4)/B4 -> 0.00096470015 | F5: Media | G5: 0.00064997512
A6: 44202 | B6: 203.19855 | C6: =(B6-B5)/B5 -> -0.025929198 | F6: Errore standard | G6: 0.00045098509
A7: 44203 | B7: 208.9809 | C7: =(B7-B6)/B6 -> 0.028456644 | F7: Mediana | G7: 0.00066179348
A8: 44204 | B8: 210.25423 | C8: =(B8-B7)/B7 -> 0.0060930483 | F8: Moda | G8: #N/A
A9: 44207 | B9: 208.21504 | C9: =(B9-B8)/B8 -> -0.0096986615 | F9: Deviazione standard | G9: 0.01652108
A10: 44208 | B10: 205.76424 | C10: =(B10-B9)/B9 -> -0.01177055 | F10: Varianza campionaria | G10: 0.0002729461
A11: 44209 | B11: 207.11411 | C11: =(B11-B10)/B10 -> 0.0065602692 | F11: Curtosi | G11: 3.7012783
A12: 44210 | B12: 203.9357 | C12: =(B12-B11)/B11 -> -0.015346158 | F12: Asimmetria | G12: 0.016242246
A13: 44211 | B13: 203.58147 | C13: =(B13-B12)/B12 -> -0.0017369827 | F13: Intervallo | G13: 0.20126839
A14: 44215 | B14: 207.20987 | C14: =(B14-B13)/B13 -> 0.017822854 | F14: Minimo | G14: -0.099931462
A15: 44216 | B15: 214.77293 | C15: =(B15-B14)/B14 -> 0.036499538 | F15: Massimo | G15: 0.10133693
A16: 44217 | B16: 215.37611 | C16: =(B16-B15)/B15 -> 0.0028084541 | F16: Somma | G16: 0.87226661
A17: 44218 | B17: 216.31425 | C17: =(B17-B16)/B16 -> 0.004355826 | F17: Conteggio | G17: 1342
A18: 44221 | B18: 219.74161 | C18: =(B18-B17)/B17 -> 0.015844323 | F18: Livello di confidenza(95,0%) | G18: 0.00088471305
A19: 44222 | B19: 222.42221 | C19: =(B19-B18)/B18 -> 0.012198887
A20: 44223 | B20: 222.96788 | C20: =(B20-B19)/B19 -> 0.0024533052
A21: 44224 | B21: 228.74074 | C21: =(B21-B20)/B20 -> 0.025890983
A22: 44225 | B22: 222.06799 | C22: =(B22-B21)/B21 -> -0.02917165
A23: 44228 | B23: 229.43005 | C23: =(B23-B22)/B22 -> 0.033152281
A24: 44229 | B24: 229.29599 | C24: =(B24-B23)/B23 -> -0.00058433374
A25: 44230 | B25: 232.63716 | C25: =(B25-B24)/B24 -> 0.014571433
A26: 44231 | B26: 231.68939 | C26: =(B26-B25)/B25 -> -0.0040740231
A27: 44232 | B27: 231.87132 | C27: =(B27-B26)/B26 -> 0.00078523466
A28: 44235 | B28: 232.12979 | C28: =(B28-B27)/B27 -> 0.0011147072
A29: 44236 | B29: 233.37436 | C29: =(B29-B28)/B28 -> 0.0053615172
A30: 44237 | B30: 232.46487 | C30: =(B30-B29)/B29 -> -0.0038971071
... A1346: 46150 | B1346: 415.12 | C1346: =(B1346-B1345)/B1345 -> -0.013427749

Sheet Rend. Settimanali MSFT
A1: RENDIMENTI SETTIMANALI DI MSFT
A3: Date | B3: Close | C3: Anno | D3: Mese | E3: Settimana ISO | F3: Giorno | G3: Data inizio settimana | H3: Data fine settimana | J3: Data inizio settimana | K3: Data fine settimana | L3: Prezzo chiusura inizio settimana | M3: Prezzo chiusura fine settimana | N3: Rendimenti settimanali
A4: 44200 | B4: 208.40652 | C4: =YEAR(A4) -> 2021 | D4: =MONTH(A4) -> 1 | E4: =_xlfn.ISOWEEKNUM(A4) -> 1 | F4: =WEEKDAY(A4,2) -> 1 | G4: =_xlfn.MINIFS($A$4:$A$1346,$C$4:$C$1346,C4,$E$4:$E$1346,E4) -> 44200 | H4: =_xlfn.MAXIFS($A$4:$A$1346,$C$4:$C$1346,C4,$E$4:$E$1346,E4) -> 44204 | J4: {=_xlfn.UNIQUE(G4:G1346)} -> 44200 | K4: {=_xlfn.UNIQUE(H4:H1346)} -> 44204 | L4: =INDEX($B$4:$B$1346,MATCH(J4,$A$4:$A$1346)) -> 208.40652 | M4: =INDEX($B$4:$B$1346,MATCH(K4,$A$4:$A$1346)) -> 210.25423 | N4: 0
A5: 44201 | B5: 208.60757 | C5: =YEAR(A5) -> 2021 | D5: =MONTH(A5) -> 1 | E5: =_xlfn.ISOWEEKNUM(A5) -> 1 | F5: =WEEKDAY(A5,2) -> 2 | G5: =_xlfn.MINIFS($A$4:$A$1346,$C$4:$C$1346,C5,$E$4:$E$1346,E5) -> 44200 | H5: =_xlfn.MAXIFS($A$4:$A$1346,$C$4:$C$1346,C5,$E$4:$E$1346,E5) -> 44204 | J5: 44207 | K5: 44211 | L5: =INDEX($B$4:$B$1346,MATCH(J5,$A$4:$A$1346)) -> 208.21504 | M5: =INDEX($B$4:$B$1346,MATCH(K5,$A$4:$A$1346)) -> 203.58147 | N5: =(M5-M4)/M4 -> -0.031736627 | Q5: Statistiche rendimenti sett. MSFT
A6: 44202 | B6: 203.19855 | C6: =YEAR(A6) -> 2021 | D6: =MONTH(A6) -> 1 | E6: =_xlfn.ISOWEEKNUM(A6) -> 1 | F6: =WEEKDAY(A6,2) -> 3 | G6: =_xlfn.MINIFS($A$4:$A$1346,$C$4:$C$1346,C6,$E$4:$E$1346,E6) -> 44200 | H6: =_xlfn.MAXIFS($A$4:$A$1346,$C$4:$C$1346,C6,$E$4:$E$1346,E6) -> 44204 | J6: 44215 | K6: 44218 | L6: =INDEX($B$4:$B$1346,MATCH(J6,$A$4:$A$1346)) -> 207.20987 | M6: =INDEX($B$4:$B$1346,MATCH(K6,$A$4:$A$1346)) -> 216.31425 | N6: =(M6-M5)/M5 -> 0.062543945
A7: 44203 | B7: 208.9809 | C7: =YEAR(A7) -> 2021 | D7: =MONTH(A7) -> 1 | E7: =_xlfn.ISOWEEKNUM(A7) -> 1 | F7: =WEEKDAY(A7,2) -> 4 | G7: =_xlfn.MINIFS($A$4:$A$1346,$C$4:$C$1346,C7,$E$4:$E$1346,E7) -> 44200 | H7: =_xlfn.MAXIFS($A$4:$A$1346,$C$4:$C$1346,C7,$E$4:$E$1346,E7) -> 44204 | J7: 44221 | K7: 44225 | L7: =INDEX($B$4:$B$1346,MATCH(J7,$A$4:$A$1346)) -> 219.74161 | M7: =INDEX($B$4:$B$1346,MATCH(K7,$A$4:$A$1346)) -> 222.06799 | N7: =(M7-M6)/M6 -> 0.026598979 | Q7: Media | R7: 0.0031462875
A8: 44204 | B8: 210.25423 | C8: =YEAR(A8) -> 2021 | D8: =MONTH(A8) -> 1 | E8: =_xlfn.ISOWEEKNUM(A8) -> 1 | F8: =WEEKDAY(A8,2) -> 5 | G8: =_xlfn.MINIFS($A$4:$A$1346,$C$4:$C$1346,C8,$E$4:$E$1346,E8) -> 44200 | H8: =_xlfn.MAXIFS($A$4:$A$1346,$C$4:$C$1346,C8,$E$4:$E$1346,E8) -> 44204 | J8: 44228 | K8: 44232 | L8: =INDEX($B$4:$B$1346,MATCH(J8,$A$4:$A$1346)) -> 229.43005 | M8: =INDEX($B$4:$B$1346,MATCH(K8,$A$4:$A$1346)) -> 231.87132 | N8: =(M8-M7)/M7 -> 0.044145621 | Q8: Errore standard | R8: 0.0022548332
A9: 44207 | B9: 208.21504 | C9: =YEAR(A9) -> 2021 | D9: =MONTH(A9) -> 1 | E9: =_xlfn.ISOWEEKNUM(A9) -> 2 | F9: =WEEKDAY(A9,2) -> 1 | G9: =_xlfn.MINIFS($A$4:$A$1346,$C$4:$C$1346,C9,$E$4:$E$1346,E9) -> 44207 | H9: =_xlfn.MAXIFS($A$4:$A$1346,$C$4:$C$1346,C9,$E$4:$E$1346,E9) -> 44211 | J9: 44235 | K9: 44239 | L9: =INDEX($B$4:$B$1346,MATCH(J9,$A$4:$A$1346)) -> 232.12979 | M9: =INDEX($B$4:$B$1346,MATCH(K9,$A$4:$A$1346)) -> 234.5423 | N9: =(M9-M8)/M8 -> 0.011519211 | Q9: Mediana | R9: 0.0039887203
A10: 44208 | B10: 205.76424 | C10: =YEAR(A10) -> 2021 | D10: =MONTH(A10) -> 1 | E10: =_xlfn.ISOWEEKNUM(A10) -> 2 | F10: =WEEKDAY(A10,2) -> 2 | G10: =_xlfn.MINIFS($A$4:$A$1346,$C$4:$C$1346,C10,$E$4:$E$1346,E10) -> 44207 | H10: =_xlfn.MAXIFS($A$4:$A$1346,$C$4:$C$1346,C10,$E$4:$E$1346,E10) -> 44211 | J10: 44243 | K10: 44246 | L10: =INDEX($B$4:$B$1346,MATCH(J10,$A$4:$A$1346)) -> 233.30728 | M10: =INDEX($B$4:$B$1346,MATCH(K10,$A$4:$A$1346)) -> 231.22508 | N10: =(M10-M9)/M9 -> -0.014143355 | Q10: Moda | R10: #N/A
A11: 44209 | B11: 207.11411 | C11: =YEAR(A11) -> 2021 | D11: =MONTH(A11) -> 1 | E11: =_xlfn.ISOWEEKNUM(A11) -> 2 | F11: =WEEKDAY(A11,2) -> 3 | G11: =_xlfn.MINIFS($A$4:$A$1346,$C$4:$C$1346,C11,$E$4:$E$1346,E11) -> 44207 | H11: =_xlfn.MAXIFS($A$4:$A$1346,$C$4:$C$1346,C11,$E$4:$E$1346,E11) -> 44211 | J11: 44249 | K11: 44253 | L11: =INDEX($B$4:$B$1346,MATCH(J11,$A$4:$A$1346)) -> 225.02629 | M11: =INDEX($B$4:$B$1346,MATCH(K11,$A$4:$A$1346)) -> 222.98248 | N11: =(M11-M10)/M10 -> -0.035647515 | Q11: Deviazione standard | R11: 0.037595583
A12: 44210 | B12: 203.9357 | C12: =YEAR(A12) -> 2021 | D12: =MONTH(A12) -> 1 | E12: =_xlfn.ISOWEEKNUM(A12) -> 2 | F12: =WEEKDAY(A12,2) -> 4 | G12: =_xlfn.MINIFS($A$4:$A$1346,$C$4:$C$1346,C12,$E$4:$E$1346,E12) -> 44207 | H12: =_xlfn.MAXIFS($A$4:$A$1346,$C$4:$C$1346,C12,$E$4:$E$1346,E12) -> 44211 | J12: 44256 | K12: 44260 | L12: =INDEX($B$4:$B$1346,MATCH(J12,$A$4:$A$1346)) -> 227.35806 | M12: =INDEX($B$4:$B$1346,MATCH(K12,$A$4:$A$1346)) -> 222.23401 | N12: =(M12-M11)/M11 -> -0.0033566499 | Q12: Varianza campionaria | R12: 0.0014134279
A13: 44211 | B13: 203.58147 | C13: =YEAR(A13) -> 2021 | D13: =MONTH(A13) -> 1 | E13: =_xlfn.ISOWEEKNUM(A13) -> 2 | F13: =WEEKDAY(A13,2) -> 5 | G13: =_xlfn.MINIFS($A$4:$A$1346,$C$4:$C$1346,C13,$E$4:$E$1346,E13) -> 44207 | H13: =_xlfn.MAXIFS($A$4:$A$1346,$C$4:$C$1346,C13,$E$4:$E$1346,E13) -> 44211 | J13: 44263 | K13: 44267 | L13: =INDEX($B$4:$B$1346,MATCH(J13,$A$4:$A$1346)) -> 218.19429 | M13: =INDEX($B$4:$B$1346,MATCH(K13,$A$4:$A$1346)) -> 226.21617 | N13: =(M13-M12)/M12 -> 0.017918781 | Q13: Curtosi | R13: 1.9342599
A14: 44215 | B14: 207.20987 | C14: =YEAR(A14) -> 2021 | D14: =MONTH(A14) -> 1 | E14: =_xlfn.ISOWEEKNUM(A14) -> 3 | F14: =WEEKDAY(A14,2) -> 2 | G14: =_xlfn.MINIFS($A$4:$A$1346,$C$4:$C$1346,C14,$E$4:$E$1346,E14) -> 44215 | H14: =_xlfn.MAXIFS($A$4:$A$1346,$C$4:$C$1346,C14,$E$4:$E$1346,E14) -> 44218 | J14: 44270 | K14: 44274 | L14: =INDEX($B$4:$B$1346,MATCH(J14,$A$4:$A$1346)) -> 225.31416 | M14: =INDEX($B$4:$B$1346,MATCH(K14,$A$4:$A$1346)) -> 221.03455 | N14: =(M14-M13)/M13 -> -0.022905636 | Q14: Asimmetria | R14: 0.44300549
A15: 44216 | B15: 214.77293 | C15: =YEAR(A15) -> 2021 | D15: =MONTH(A15) -> 1 | E15: =_xlfn.ISOWEEKNUM(A15) -> 3 | F15: =WEEKDAY(A15,2) -> 3 | G15: =_xlfn.MINIFS($A$4:$A$1346,$C$4:$C$1346,C15,$E$4:$E$1346,E15) -> 44215 | H15: =_xlfn.MAXIFS($A$4:$A$1346,$C$4:$C$1346,C15,$E$4:$E$1346,E15) -> 44218 | J15: 44277 | K15: 44281 | L15: =INDEX($B$4:$B$1346,MATCH(J15,$A$4:$A$1346)) -> 226.44646 | M15: =INDEX($B$4:$B$1346,MATCH(K15,$A$4:$A$1346)) -> 226.91663 | N15: =(M15-M14)/M14 -> 0.026611587 | Q15: Intervallo | R15: 0.28005944
A16: 44217 | B16: 215.37611 | C16: =YEAR(A16) -> 2021 | D16: =MONTH(A16) -> 1 | E16: =_xlfn.ISOWEEKNUM(A16) -> 3 | F16: =WEEKDAY(A16,2) -> 4 | G16: =_xlfn.MINIFS($A$4:$A$1346,$C$4:$C$1346,C16,$E$4:$E$1346,E16) -> 44215 | H16: =_xlfn.MAXIFS($A$4:$A$1346,$C$4:$C$1346,C16,$E$4:$E$1346,E16) -> 44218 | J16: 44284 | K16: 44287 | L16: =INDEX($B$4:$B$1346,MATCH(J16,$A$4:$A$1346)) -> 225.72681 | M16: =INDEX($B$4:$B$1346,MATCH(K16,$A$4:$A$1346)) -> 232.54926 | N16: =(M16-M15)/M15 -> 0.024822462 | Q16: Minimo | R16: -0.14006425
A17: 44218 | B17: 216.31425 | C17: =YEAR(A17) -> 2021 | D17: =MONTH(A17) -> 1 | E17: =_xlfn.ISOWEEKNUM(A17) -> 3 | F17: =WEEKDAY(A17,2) -> 5 | G17: =_xlfn.MINIFS($A$4:$A$1346,$C$4:$C$1346,C17,$E$4:$E$1346,E17) -> 44215 | H17: =_xlfn.MAXIFS($A$4:$A$1346,$C$4:$C$1346,C17,$E$4:$E$1346,E17) -> 44218 | J17: 44291 | K17: 44295 | L17: =INDEX($B$4:$B$1346,MATCH(J17,$A$4:$A$1346)) -> 238.9975 | M17: =INDEX($B$4:$B$1346,MATCH(K17,$A$4:$A$1346)) -> 245.50334 | N17: =(M17-M16)/M16 -> 0.055704699 | Q17: Massimo | R17: 0.13999518
A18: 44221 | B18: 219.74161 | C18: =YEAR(A18) -> 2021 | D18: =MONTH(A18) -> 1 | E18: =_xlfn.ISOWEEKNUM(A18) -> 4 | F18: =WEEKDAY(A18,2) -> 1 | G18: =_xlfn.MINIFS($A$4:$A$1346,$C$4:$C$1346,C18,$E$4:$E$1346,E18) -> 44221 | H18: =_xlfn.MAXIFS($A$4:$A$1346,$C$4:$C$1346,C18,$E$4:$E$1346,E18) -> 44225 | J18: 44298 | K18: 44302 | L18: =INDEX($B$4:$B$1346,MATCH(J18,$A$4:$A$1346)) -> 245.5609 | M18: =INDEX($B$4:$B$1346,MATCH(K18,$A$4:$A$1346)) -> 250.19553 | N18: =(M18-M17)/M17 -> 0.019112507 | Q18: Somma | R18: 0.87466793
A19: 44222 | B19: 222.42221 | C19: =YEAR(A19) -> 2021 | D19: =MONTH(A19) -> 1 | E19: =_xlfn.ISOWEEKNUM(A19) -> 4 | F19: =WEEKDAY(A19,2) -> 2 | G19: =_xlfn.MINIFS($A$4:$A$1346,$C$4:$C$1346,C19,$E$4:$E$1346,E19) -> 44221 | H19: =_xlfn.MAXIFS($A$4:$A$1346,$C$4:$C$1346,C19,$E$4:$E$1346,E19) -> 44225 | J19: 44305 | K19: 44309 | L19: =INDEX($B$4:$B$1346,MATCH(J19,$A$4:$A$1346)) -> 248.27643 | M19: =INDEX($B$4:$B$1346,MATCH(K19,$A$4:$A$1346)) -> 250.589 | N19: =(M19-M18)/M18 -> 0.0015726836 | Q19: Conteggio | R19: 278
A20: 44223 | B20: 222.96788 | C20: =YEAR(A20) -> 2021 | D20: =MONTH(A20) -> 1 | E20: =_xlfn.ISOWEEKNUM(A20) -> 4 | F20: =WEEKDAY(A20,2) -> 3 | G20: =_xlfn.MINIFS($A$4:$A$1346,$C$4:$C$1346,C20,$E$4:$E$1346,E20) -> 44221 | H20: =_xlfn.MAXIFS($A$4:$A$1346,$C$4:$C$1346,C20,$E$4:$E$1346,E20) -> 44225 | J20: 44312 | K20: 44316 | L20: =INDEX($B$4:$B$1346,MATCH(J20,$A$4:$A$1346)) -> 250.97278 | M20: =INDEX($B$4:$B$1346,MATCH(K20,$A$4:$A$1346)) -> 241.98174 | N20: =(M20-M19)/M19 -> -0.034348152 | Q20: Livello di confidenza(95,0%) | R20: 0.0044387859
A21: 44224 | B21: 228.74074 | C21: =YEAR(A21) -> 2021 | D21: =MONTH(A21) -> 1 | E21: =_xlfn.ISOWEEKNUM(A21) -> 4 | F21: =WEEKDAY(A21,2) -> 4 | G21: =_xlfn.MINIFS($A$4:$A$1346,$C$4:$C$1346,C21,$E$4:$E$1346,E21) -> 44221 | H21: =_xlfn.MAXIFS($A$4:$A$1346,$C$4:$C$1346,C21,$E$4:$E$1346,E21) -> 44225 | J21: 44319 | K21: 44323 | L21: =INDEX($B$4:$B$1346,MATCH(J21,$A$4:$A$1346)) -> 241.67467 | M21: =INDEX($B$4:$B$1346,MATCH(K21,$A$4:$A$1346)) -> 242.25041 | N21: =(M21-M20)/M20 -> 0.0011103183
A22: 44225 | B22: 222.06799 | C22: =YEAR(A22) -> 2021 | D22: =MONTH(A22) -> 1 | E22: =_xlfn.ISOWEEKNUM(A22) -> 4 | F22: =WEEKDAY(A22,2) -> 5 | G22: =_xlfn.MINIFS($A$4:$A$1346,$C$4:$C$1346,C22,$E$4:$E$1346,E22) -> 44221 | H22: =_xlfn.MAXIFS($A$4:$A$1346,$C$4:$C$1346,C22,$E$4:$E$1346,E22) -> 44225 | J22: 44326 | K22: 44330 | L22: =INDEX($B$4:$B$1346,MATCH(J22,$A$4:$A$1346)) -> 237.18393 | M22: =INDEX($B$4:$B$1346,MATCH(K22,$A$4:$A$1346)) -> 238.11472 | N22: =(M22-M21)/M21 -> -0.017071989
A23: 44228 | B23: 229.43005 | C23: =YEAR(A23) -> 2021 | D23: =MONTH(A23) -> 2 | E23: =_xlfn.ISOWEEKNUM(A23) -> 5 | F23: =WEEKDAY(A23,2) -> 1 | G23: =_xlfn.MINIFS($A$4:$A$1346,$C$4:$C$1346,C23,$E$4:$E$1346,E23) -> 44228 | H23: =_xlfn.MAXIFS($A$4:$A$1346,$C$4:$C$1346,C23,$E$4:$E$1346,E23) -> 44232 | J23: 44333 | K23: 44337 | L23: =INDEX($B$4:$B$1346,MATCH(J23,$A$4:$A$1346)) -> 235.26483 | M23: =INDEX($B$4:$B$1346,MATCH(K23,$A$4:$A$1346)) -> 235.79845 | N23: =(M23-M22)/M22 -> -0.0097275337
A24: 44229 | B24: 229.29599 | C24: =YEAR(A24) -> 2021 | D24: =MONTH(A24) -> 2 | E24: =_xlfn.ISOWEEKNUM(A24) -> 5 | F24: =WEEKDAY(A24,2) -> 2 | G24: =_xlfn.MINIFS($A$4:$A$1346,$C$4:$C$1346,C24,$E$4:$E$1346,E24) -> 44228 | H24: =_xlfn.MAXIFS($A$4:$A$1346,$C$4:$C$1346,C24,$E$4:$E$1346,E24) -> 44232 | J24: 44340 | K24: 44344 | L24: =INDEX($B$4:$B$1346,MATCH(J24,$A$4:$A$1346)) -> 241.194 | M24: =INDEX($B$4:$B$1346,MATCH(K24,$A$4:$A$1346)) -> 240.13605 | N24: =(M24-M23)/M23 -> 0.018395374
A25: 44230 | B25: 232.63716 | C25: =YEAR(A25) -> 2021 | D25: =MONTH(A25) -> 2 | E25: =_xlfn.ISOWEEKNUM(A25) -> 5 | F25: =WEEKDAY(A25,2) -> 3 | G25: =_xlfn.MINIFS($A$4:$A$1346,$C$4:$C$1346,C25,$E$4:$E$1346,E25) -> 44228 | H25: =_xlfn.MAXIFS($A$4:$A$1346,$C$4:$C$1346,C25,$E$4:$E$1346,E25) -> 44232 | J25: 44348 | K25: 44351 | L25: =INDEX($B$4:$B$1346,MATCH(J25,$A$4:$A$1346)) -> 237.94315 | M25: =INDEX($B$4:$B$1346,MATCH(K25,$A$4:$A$1346)) -> 241.20363 | N25: =(M25-M24)/M24 -> 0.0044457348
A26: 44231 | B26: 231.68939 | C26: =YEAR(A26) -> 2021 | D26: =MONTH(A26) -> 2 | E26: =_xlfn.ISOWEEKNUM(A26) -> 5 | F26: =WEEKDAY(A26,2) -> 4 | G26: =_xlfn.MINIFS($A$4:$A$1346,$C$4:$C$1346,C26,$E$4:$E$1346,E26) -> 44228 | H26: =_xlfn.MAXIFS($A$4:$A$1346,$C$4:$C$1346,C26,$E$4:$E$1346,E26) -> 44232 | J26: 44354 | K26: 44358 | L26: =INDEX($B$4:$B$1346,MATCH(J26,$A$4:$A$1346)) -> 244.1082 | M26: =INDEX($B$4:$B$1346,MATCH(K26,$A$4:$A$1346)) -> 248.03224 | N26: =(M26-M25)/M25 -> 0.028310574
A27: 44232 | B27: 231.87132 | C27: =YEAR(A27) -> 2021 | D27: =MONTH(A27) -> 2 | E27: =_xlfn.ISOWEEKNUM(A27) -> 5 | F27: =WEEKDAY(A27,2) -> 5 | G27: =_xlfn.MINIFS($A$4:$A$1346,$C$4:$C$1346,C27,$E$4:$E$1346,E27) -> 44228 | H27: =_xlfn.MAXIFS($A$4:$A$1346,$C$4:$C$1346,C27,$E$4:$E$1346,E27) -> 44232 | J27: 44361 | K27: 44365 | L27: =INDEX($B$4:$B$1346,MATCH(J27,$A$4:$A$1346)) -> 249.95578 | M27: =INDEX($B$4:$B$1346,MATCH(K27,$A$4:$A$1346)) -> 249.51337 | N27: =(M27-M26)/M26 -> 0.0059715014
A28: 44235 | B28: 232.12979 | C28: =YEAR(A28) -> 2021 | D28: =MONTH(A28) -> 2 | E28: =_xlfn.ISOWEEKNUM(A28) -> 6 | F28: =WEEKDAY(A28,2) -> 1 | G28: =_xlfn.MINIFS($A$4:$A$1346,$C$4:$C$1346,C28,$E$4:$E$1346,E28) -> 44235 | H28: =_xlfn.MAXIFS($A$4:$A$1346,$C$4:$C$1346,C28,$E$4:$E$1346,E28) -> 44239 | J28: 44368 | K28: 44372 | L28: =INDEX($B$4:$B$1346,MATCH(J28,$A$4:$A$1346)) -> 252.591 | M28: =INDEX($B$4:$B$1346,MATCH(K28,$A$4:$A$1346)) -> 254.88971 | N28: =(M28-M27)/M27 -> 0.021547314
A29: 44236 | B29: 233.37436 | C29: =YEAR(A29) -> 2021 | D29: =MONTH(A29) -> 2 | E29: =_xlfn.ISOWEEKNUM(A29) -> 6 | F29: =WEEKDAY(A29,2) -> 2 | G29: =_xlfn.MINIFS($A$4:$A$1346,$C$4:$C$1346,C29,$E$4:$E$1346,E29) -> 44235 | H29: =_xlfn.MAXIFS($A$4:$A$1346,$C$4:$C$1346,C29,$E$4:$E$1346,E29) -> 44239 | J29: 44375 | K29: 44379 | L29: =INDEX($B$4:$B$1346,MATCH(J29,$A$4:$A$1346)) -> 258.44827 | M29: =INDEX($B$4:$B$1346,MATCH(K29,$A$4:$A$1346)) -> 267.03687 | N29: =(M29-M28)/M28 -> 0.047656517
A30: 44237 | B30: 232.46487 | C30: =YEAR(A30) -> 2021 | D30: =MONTH(A30) -> 2 | E30: =_xlfn.ISOWEEKNUM(A30) -> 6 | F30: =WEEKDAY(A30,2) -> 3 | G30: =_xlfn.MINIFS($A$4:$A$1346,$C$4:$C$1346,C30,$E$4:$E$1346,E30) -> 44235 | H30: =_xlfn.MAXIFS($A$4:$A$1346,$C$4:$C$1346,C30,$E$4:$E$1346,E30) -> 44239 | J30: 44383 | K30: 44386 | L30: =INDEX($B$4:$B$1346,MATCH(J30,$A$4:$A$1346)) -> 267.04657 | M30: =INDEX($B$4:$B$1346,MATCH(K30,$A$4:$A$1346)) -> 267.31583 | N30: =(M30-M29)/M29 -> 0.0010446542
A31: 44238 | B31: 234.06361 | C31: =YEAR(A31) -> 2021 | D31: =MONTH(A31) -> 2 | E31: =_xlfn.ISOWEEKNUM(A31) -> 6 | F31: =WEEKDAY(A31,2) -> 4 | G31: =_xlfn.MINIFS($A$4:$A$1346,$C$4:$C$1346,C31,$E$4:$E$1346,E31) -> 44235 | H31: =_xlfn.MAXIFS($A$4:$A$1346,$C$4:$C$1346,C31,$E$4:$E$1346,E31) -> 44239 | J31: 44389 | K31: 44393 | L31: =INDEX($B$4:$B$1346,MATCH(J31,$A$4:$A$1346)) -> 266.71948 | M31: =INDEX($B$4:$B$1346,MATCH(K31,$A$4:$A$1346)) -> 270.0184 | N31: =(M31-M30)/M30 -> 0.010110047
A32: 44239 | B32: 234.5423 | C32: =YEAR(A32) -> 2021 | D32: =MONTH(A32) -> 2 | E32: =_xlfn.ISOWEEKNUM(A32) -> 6 | F32: =WEEKDAY(A32,2) -> 5 | G32: =_xlfn.MINIFS($A$4:$A$1346,$C$4:$C$1346,C32,$E$4:$E$1346,E32) -> 44235 | H32: =_xlfn.MAXIFS($A$4:$A$1346,$C$4:$C$1346,C32,$E$4:$E$1346,E32) -> 44239 | J32: 44396 | K32: 44400 | L32: =INDEX($B$4:$B$1346,MATCH(J32,$A$4:$A$1346)) -> 266.42133 | M32: =INDEX($B$4:$B$1346,MATCH(K32,$A$4:$A$1346)) -> 278.59744 | N32: =(M32-M31)/M31 -> 0.031772059
... A282: 44601 | B282: 300.43576 | C282: =YEAR(A282) -> 2022 | D282: =MONTH(A282) -> 2 | E282: =_xlfn.ISOWEEKNUM(A282) -> 6 | F282: =WEEKDAY(A282,2) -> 3 | G282: =_xlfn.MINIFS($A$4:$A$1346,$C$4:$C$1346,C282,$E$4:$E$1346,E282) -> 44599 | H282: =_xlfn.MAXIFS($A$4:$A$1346,$C$4:$C$1346,C282,$E$4:$E$1346,E282) -> 44603 | J282: 46146 | K282: 46150 | L282: =INDEX($B$4:$B$1346,MATCH(J282,$A$4:$A$1346)) -> 413.62 | M282: =INDEX($B$4:$B$1346,MATCH(K282,$A$4:$A$1346)) -> 415.12 | N282: =(M282-M281)/M281 -> 0.0016407506
A283: 44602 | B283: 291.9115 | C283: =YEAR(A283) -> 2022 | D283: =MONTH(A283) -> 2 | E283: =_xlfn.ISOWEEKNUM(A283) -> 6 | F283: =WEEKDAY(A283,2) -> 4 | G283: =_xlfn.MINIFS($A$4:$A$1346,$C$4:$C$1346,C283,$E$4:$E$1346,E283) -> 44599 | H283: =_xlfn.MAXIFS($A$4:$A$1346,$C$4:$C$1346,C283,$E$4:$E$1346,E283) -> 44603
A284: 44603 | B284: 284.82559 | C284: =YEAR(A284) -> 2022 | D284: =MONTH(A284) -> 2 | E284: =_xlfn.ISOWEEKNUM(A284) -> 6 | F284: =WEEKDAY(A284,2) -> 5 | G284: =_xlfn.MINIFS($A$4:$A$1346,$C$4:$C$1346,C284,$E$4:$E$1346,E284) -> 44599 | H284: =_xlfn.MAXIFS($A$4:$A$1346,$C$4:$C$1346,C284,$E$4:$E$1346,E284) -> 44603
A285: 44606 | B285: 284.78696 | C285: =YEAR(A285) -> 2022 | D285: =MONTH(A285) -> 2 | E285: =_xlfn.ISOWEEKNUM(A285) -> 7 | F285: =WEEKDAY(A285,2) -> 1 | G285: =_xlfn.MINIFS($A$4:$A$1346,$C$4:$C$1346,C285,$E$4:$E$1346,E285) -> 44606 | H285: =_xlfn.MAXIFS($A$4:$A$1346,$C$4:$C$1346,C285,$E$4:$E$1346,E285) -> 44610
A286: 44607 | B286: 290.06754 | C286: =YEAR(A286) -> 2022 | D286: =MONTH(A286) -> 2 | E286: =_xlfn.ISOWEEKNUM(A286) -> 7 | F286: =WEEKDAY(A286,2) -> 2 | G286: =_xlfn.MINIFS($A$4:$A$1346,$C$4:$C$1346,C286,$E$4:$E$1346,E286) -> 44606 | H286: =_xlfn.MAXIFS($A$4:$A$1346,$C$4:$C$1346,C286,$E$4:$E$1346,E286) -> 44610
A287: 44608 | B287: 289.72903 | C287: =YEAR(A287) -> 2022 | D287: =MONTH(A287) -> 2 | E287: =_xlfn.ISOWEEKNUM(A287) -> 7 | F287: =WEEKDAY(A287,2) -> 3 | G287: =_xlfn.MINIFS($A$4:$A$1346,$C$4:$C$1346,C287,$E$4:$E$1346,E287) -> 44606 | H287: =_xlfn.MAXIFS($A$4:$A$1346,$C$4:$C$1346,C287,$E$4:$E$1346,E287) -> 44610
A288: 44609 | B288: 281.24518 | C288: =YEAR(A288) -> 2022 | D288: =MONTH(A288) -> 2 | E288: =_xlfn.ISOWEEKNUM(A288) -> 7 | F288: =WEEKDAY(A288,2) -> 4 | G288: =_xlfn.MINIFS($A$4:$A$1346,$C$4:$C$1346,C288,$E$4:$E$1346,E288) -> 44606 | H288: =_xlfn.MAXIFS($A$4:$A$1346,$C$4:$C$1346,C288,$E$4:$E$1346,E288) -> 44610
A289: 44610 | B289: 278.53647 | C289: =YEAR(A289) -> 2022 | D289: =MONTH(A289) -> 2 | E289: =_xlfn.ISOWEEKNUM(A289) -> 7 | F289: =WEEKDAY(A289,2) -> 5 | G289: =_xlfn.MINIFS($A$4:$A$1346,$C$4:$C$1346,C289,$E$4:$E$1346,E289) -> 44606 | H289: =_xlfn.MAXIFS($A$4:$A$1346,$C$4:$C$1346,C289,$E$4:$E$1346,E289) -> 44610
A290: 44614 | B290: 278.33331 | C290: =YEAR(A290) -> 2022 | D290: =MONTH(A290) -> 2 | E290: =_xlfn.ISOWEEKNUM(A290) -> 8 | F290: =WEEKDAY(A290,2) -> 2 | G290: =_xlfn.MINIFS($A$4:$A$1346,$C$4:$C$1346,C290,$E$4:$E$1346,E290) -> 44614 | H290: =_xlfn.MAXIFS($A$4:$A$1346,$C$4:$C$1346,C290,$E$4:$E$1346,E290) -> 44617
...

Sheet Rend. Mensili MSFT
A1: RENDIMENTI MENSILI DI MSFT
A3: Date | B3: Close | C3: Anno | D3: Mese | E3: Settimana ISO | F3: Giorno | G3: Data inizio mese | H3: Data fine mese | J3: Data inizio mese | K3: Data fine mese | L3: Prezzo chiusura inizio mese | M3: Prezzo chiusura fine mese | N3: Rendimenti mensili
A4: 44200 | B4: 208.40652 | C4: =YEAR(A4) -> 2021 | D4: =MONTH(A4) -> 1 | E4: =_xlfn.ISOWEEKNUM(A4) -> 1 | F4: =WEEKDAY(A4,2) -> 1 | G4: =_xlfn.MINIFS($A$4:$A$1346,$C$4:$C$1346,C4,$D$4:$D$1346,D4) -> 44200 | H4: =_xlfn.MAXIFS($A$4:$A$1346,$C$4:$C$1346,C4,$D$4:$D$1346,D4) -> 44225 | J4: {=_xlfn.UNIQUE(G4:G1346)} -> 44200 | K4: {=_xlfn.UNIQUE(H4:H1346)} -> 44225 | L4: =INDEX($B$4:$B$1346,MATCH(J4,$A$4:$A$1346)) -> 208.40652 | M4: =INDEX($B$4:$B$1346,MATCH(K4,$A$4:$A$1346)) -> 222.06799 | N4: 0 | Q4: Statistiche rendimenti mensili MSFT
A5: 44201 | B5: 208.60757 | C5: =YEAR(A5) -> 2021 | D5: =MONTH(A5) -> 1 | E5: =_xlfn.ISOWEEKNUM(A5) -> 1 | F5: =WEEKDAY(A5,2) -> 2 | G5: =_xlfn.MINIFS($A$4:$A$1346,$C$4:$C$1346,C5,$D$4:$D$1346,D5) -> 44200 | H5: =_xlfn.MAXIFS($A$4:$A$1346,$C$4:$C$1346,C5,$D$4:$D$1346,D5) -> 44225 | J5: 44228 | K5: 44253 | L5: =INDEX($B$4:$B$1346,MATCH(J5,$A$4:$A$1346)) -> 229.43005 | M5: =INDEX($B$4:$B$1346,MATCH(K5,$A$4:$A$1346)) -> 222.98248 | N5: =(M5-M4)/M4 -> 0.0041180619
A6: 44202 | B6: 203.19855 | C6: =YEAR(A6) -> 2021 | D6: =MONTH(A6) -> 1 | E6: =_xlfn.ISOWEEKNUM(A6) -> 1 | F6: =WEEKDAY(A6,2) -> 3 | G6: =_xlfn.MINIFS($A$4:$A$1346,$C$4:$C$1346,C6,$D$4:$D$1346,D6) -> 44200 | H6: =_xlfn.MAXIFS($A$4:$A$1346,$C$4:$C$1346,C6,$D$4:$D$1346,D6) -> 44225 | J6: 44256 | K6: 44286 | L6: =INDEX($B$4:$B$1346,MATCH(J6,$A$4:$A$1346)) -> 227.35806 | M6: =INDEX($B$4:$B$1346,MATCH(K6,$A$4:$A$1346)) -> 226.23538 | N6: =(M6-M5)/M5 -> 0.014588138 | Q6: Media | R6: 0.011980801
A7: 44203 | B7: 208.9809 | C7: =YEAR(A7) -> 2021 | D7: =MONTH(A7) -> 1 | E7: =_xlfn.ISOWEEKNUM(A7) -> 1 | F7: =WEEKDAY(A7,2) -> 4 | G7: =_xlfn.MINIFS($A$4:$A$1346,$C$4:$C$1346,C7,$D$4:$D$1346,D7) -> 44200 | H7: =_xlfn.MAXIFS($A$4:$A$1346,$C$4:$C$1346,C7,$D$4:$D$1346,D7) -> 44225 | J7: 44287 | K7: 44316 | L7: =INDEX($B$4:$B$1346,MATCH(J7,$A$4:$A$1346)) -> 232.54926 | M7: =INDEX($B$4:$B$1346,MATCH(K7,$A$4:$A$1346)) -> 241.98174 | N7: =(M7-M6)/M6 -> 0.069601638 | Q7: Errore standard | R7: 0.0083652125
A8: 44204 | B8: 210.25423 | C8: =YEAR(A8) -> 2021 | D8: =MONTH(A8) -> 1 | E8: =_xlfn.ISOWEEKNUM(A8) -> 1 | F8: =WEEKDAY(A8,2) -> 5 | G8: =_xlfn.MINIFS($A$4:$A$1346,$C$4:$C$1346,C8,$D$4:$D$1346,D8) -> 44200 | H8: =_xlfn.MAXIFS($A$4:$A$1346,$C$4:$C$1346,C8,$D$4:$D$1346,D8) -> 44225 | J8: 44319 | K8: 44344 | L8: =INDEX($B$4:$B$1346,MATCH(J8,$A$4:$A$1346)) -> 241.67467 | M8: =INDEX($B$4:$B$1346,MATCH(K8,$A$4:$A$1346)) -> 240.13605 | N8: =(M8-M7)/M7 -> -0.007627385 | Q8: Mediana | R8: 0.0065679036
A9: 44207 | B9: 208.21504 | C9: =YEAR(A9) -> 2021 | D9: =MONTH(A9) -> 1 | E9: =_xlfn.ISOWEEKNUM(A9) -> 2 | F9: =WEEKDAY(A9,2) -> 1 | G9: =_xlfn.MINIFS($A$4:$A$1346,$C$4:$C$1346,C9,$D$4:$D$1346,D9) -> 44200 | H9: =_xlfn.MAXIFS($A$4:$A$1346,$C$4:$C$1346,C9,$D$4:$D$1346,D9) -> 44225 | J9: 44348 | K9: 44377 | L9: =INDEX($B$4:$B$1346,MATCH(J9,$A$4:$A$1346)) -> 237.94315 | M9: =INDEX($B$4:$B$1346,MATCH(K9,$A$4:$A$1346)) -> 260.54498 | N9: =(M9-M8)/M8 -> 0.084989054 | Q9: Moda | R9: #N/A
A10: 44208 | B10: 205.76424 | C10: =YEAR(A10) -> 2021 | D10: =MONTH(A10) -> 1 | E10: =_xlfn.ISOWEEKNUM(A10) -> 2 | F10: =WEEKDAY(A10,2) -> 2 | G10: =_xlfn.MINIFS($A$4:$A$1346,$C$4:$C$1346,C10,$D$4:$D$1346,D10) -> 44200 | H10: =_xlfn.MAXIFS($A$4:$A$1346,$C$4:$C$1346,C10,$D$4:$D$1346,D10) -> 44225 | J10: 44378 | K10: 44407 | L10: =INDEX($B$4:$B$1346,MATCH(J10,$A$4:$A$1346)) -> 261.21817 | M10: =INDEX($B$4:$B$1346,MATCH(K10,$A$4:$A$1346)) -> 274.01935 | N10: =(M10-M9)/M9 -> 0.05171608 | Q10: Deviazione standard | R10: 0.0669217
A11: 44209 | B11: 207.11411 | C11: =YEAR(A11) -> 2021 | D11: =MONTH(A11) -> 1 | E11: =_xlfn.ISOWEEKNUM(A11) -> 2 | F11: =WEEKDAY(A11,2) -> 3 | G11: =_xlfn.MINIFS($A$4:$A$1346,$C$4:$C$1346,C11,$D$4:$D$1346,D11) -> 44200 | H11: =_xlfn.MAXIFS($A$4:$A$1346,$C$4:$C$1346,C11,$D$4:$D$1346,D11) -> 44225 | J11: 44410 | K11: 44439 | L11: =INDEX($B$4:$B$1346,MATCH(J11,$A$4:$A$1346)) -> 273.93292 | M11: =INDEX($B$4:$B$1346,MATCH(K11,$A$4:$A$1346)) -> 290.89664 | N11: =(M11-M10)/M10 -> 0.061591595 | Q11: Varianza campionaria | R11: 0.004478514
A12: 44210 | B12: 203.9357 | C12: =YEAR(A12) -> 2021 | D12: =MONTH(A12) -> 1 | E12: =_xlfn.ISOWEEKNUM(A12) -> 2 | F12: =WEEKDAY(A12,2) -> 4 | G12: =_xlfn.MINIFS($A$4:$A$1346,$C$4:$C$1346,C12,$D$4:$D$1346,D12) -> 44200 | H12: =_xlfn.MAXIFS($A$4:$A$1346,$C$4:$C$1346,C12,$D$4:$D$1346,D12) -> 44225 | J12: 44440 | K12: 44469 | L12: =INDEX($B$4:$B$1346,MATCH(J12,$A$4:$A$1346)) -> 290.8483 | M12: =INDEX($B$4:$B$1346,MATCH(K12,$A$4:$A$1346)) -> 271.66281 | N12: =(M12-M11)/M11 -> -0.066119106 | Q12: Curtosi | R12: -0.29153618
A13: 44211 | B13: 203.58147 | C13: =YEAR(A13) -> 2021 | D13: =MONTH(A13) -> 1 | E13: =_xlfn.ISOWEEKNUM(A13) -> 2 | F13: =WEEKDAY(A13,2) -> 5 | G13: =_xlfn.MINIFS($A$4:$A$1346,$C$4:$C$1346,C13,$D$4:$D$1346,D13) -> 44200 | H13: =_xlfn.MAXIFS($A$4:$A$1346,$C$4:$C$1346,C13,$D$4:$D$1346,D13) -> 44225 | J13: 44470 | K13: 44498 | L13: =INDEX($B$4:$B$1346,MATCH(J13,$A$4:$A$1346)) -> 278.58154 | M13: =INDEX($B$4:$B$1346,MATCH(K13,$A$4:$A$1346)) -> 319.55453 | N13: =(M13-M12)/M12 -> 0.17629106 | Q13: Asimmetria | R13: 0.31862476
A14: 44215 | B14: 207.20987 | C14: =YEAR(A14) -> 2021 | D14: =MONTH(A14) -> 1 | E14: =_xlfn.ISOWEEKNUM(A14) -> 3 | F14: =WEEKDAY(A14,2) -> 2 | G14: =_xlfn.MINIFS($A$4:$A$1346,$C$4:$C$1346,C14,$D$4:$D$1346,D14) -> 44200 | H14: =_xlfn.MAXIFS($A$4:$A$1346,$C$4:$C$1346,C14,$D$4:$D$1346,D14) -> 44225 | J14: 44501 | K14: 44530 | L14: =INDEX($B$4:$B$1346,MATCH(J14,$A$4:$A$1346)) -> 317.38638 | M14: =INDEX($B$4:$B$1346,MATCH(K14,$A$4:$A$1346)) -> 319.14484 | N14: =(M14-M13)/M13 -> -0.0012820925 | Q14: Intervallo | R14: 0.28656359
A15: 44216 | B15: 214.77293 | C15: =YEAR(A15) -> 2021 | D15: =MONTH(A15) -> 1 | E15: =_xlfn.ISOWEEKNUM(A15) -> 3 | F15: =WEEKDAY(A15,2) -> 3 | G15: =_xlfn.MINIFS($A$4:$A$1346,$C$4:$C$1346,C15,$D$4:$D$1346,D15) -> 44200 | H15: =_xlfn.MAXIFS($A$4:$A$1346,$C$4:$C$1346,C15,$D$4:$D$1346,D15) -> 44225 | J15: 44531 | K15: 44561 | L15: =INDEX($B$4:$B$1346,MATCH(J15,$A$4:$A$1346)) -> 318.65253 | M15: =INDEX($B$4:$B$1346,MATCH(K15,$A$4:$A$1346)) -> 324.67642 | N15: =(M15-M14)/M14 -> 0.017332524 | Q15: Minimo | R15: -0.11027253
A16: 44217 | B16: 215.37611 | C16: =YEAR(A16) -> 2021 | D16: =MONTH(A16) -> 1 | E16: =_xlfn.ISOWEEKNUM(A16) -> 3 | F16: =WEEKDAY(A16,2) -> 4 | G16: =_xlfn.MINIFS($A$4:$A$1346,$C$4:$C$1346,C16,$D$4:$D$1346,D16) -> 44200 | H16: =_xlfn.MAXIFS($A$4:$A$1346,$C$4:$C$1346,C16,$D$4:$D$1346,D16) -> 44225 | J16: 44564 | K16: 44592 | L16: =INDEX($B$4:$B$1346,MATCH(J16,$A$4:$A$1346)) -> 323.16074 | M16: =INDEX($B$4:$B$1346,MATCH(K16,$A$4:$A$1346)) -> 300.21368 | N16: =(M16-M15)/M15 -> -0.075344978 | Q16: Massimo | R16: 0.17629106
A17: 44218 | B17: 216.31425 | C17: =YEAR(A17) -> 2021 | D17: =MONTH(A17) -> 1 | E17: =_xlfn.ISOWEEKNUM(A17) -> 3 | F17: =WEEKDAY(A17,2) -> 5 | G17: =_xlfn.MINIFS($A$4:$A$1346,$C$4:$C$1346,C17,$D$4:$D$1346,D17) -> 44200 | H17: =_xlfn.MAXIFS($A$4:$A$1346,$C$4:$C$1346,C17,$D$4:$D$1346,D17) -> 44225 | J17: 44593 | K17: 44620 | L17: =INDEX($B$4:$B$1346,MATCH(J17,$A$4:$A$1346)) -> 298.07053 | M17: =INDEX($B$4:$B$1346,MATCH(K17,$A$4:$A$1346)) -> 289.04221 | N17: =(M17-M16)/M16 -> -0.037211756 | Q17: Somma | R17: 0.76677127
A18: 44221 | B18: 219.74161 | C18: =YEAR(A18) -> 2021 | D18: =MONTH(A18) -> 1 | E18: =_xlfn.ISOWEEKNUM(A18) -> 4 | F18: =WEEKDAY(A18,2) -> 1 | G18: =_xlfn.MINIFS($A$4:$A$1346,$C$4:$C$1346,C18,$D$4:$D$1346,D18) -> 44200 | H18: =_xlfn.MAXIFS($A$4:$A$1346,$C$4:$C$1346,C18,$D$4:$D$1346,D18) -> 44225 | J18: 44621 | K18: 44651 | L18: =INDEX($B$4:$B$1346,MATCH(J18,$A$4:$A$1346)) -> 285.32742 | M18: =INDEX($B$4:$B$1346,MATCH(K18,$A$4:$A$1346)) -> 298.25159 | N18: =(M18-M17)/M17 -> 0.031861717 | Q18: Conteggio | R18: 64
A19: 44222 | B19: 222.42221 | C19: =YEAR(A19) -> 2021 | D19: =MONTH(A19) -> 1 | E19: =_xlfn.ISOWEEKNUM(A19) -> 4 | F19: =WEEKDAY(A19,2) -> 2 | G19: =_xlfn.MINIFS($A$4:$A$1346,$C$4:$C$1346,C19,$D$4:$D$1346,D19) -> 44200 | H19: =_xlfn.MAXIFS($A$4:$A$1346,$C$4:$C$1346,C19,$D$4:$D$1346,D19) -> 44225 | J19: 44652 | K19: 44680 | L19: =INDEX($B$4:$B$1346,MATCH(J19,$A$4:$A$1346)) -> 299.32541 | M19: =INDEX($B$4:$B$1346,MATCH(K19,$A$4:$A$1346)) -> 268.46613 | N19: =(M19-M18)/M18 -> -0.0998669 | Q19: Livello di confidenza(95,0%) | R19: 0.016716543
A20: 44223 | B20: 222.96788 | C20: =YEAR(A20) -> 2021 | D20: =MONTH(A20) -> 1 | E20: =_xlfn.ISOWEEKNUM(A20) -> 4 | F20: =WEEKDAY(A20,2) -> 3 | G20: =_xlfn.MINIFS($A$4:$A$1346,$C$4:$C$1346,C20,$D$4:$D$1346,D20) -> 44200 | H20: =_xlfn.MAXIFS($A$4:$A$1346,$C$4:$C$1346,C20,$D$4:$D$1346,D20) -> 44225 | J20: 44683 | K20: 44712 | L20: =INDEX($B$4:$B$1346,MATCH(J20,$A$4:$A$1346)) -> 275.18939 | M20: =INDEX($B$4:$B$1346,MATCH(K20,$A$4:$A$1346)) -> 263.61298 | N20: =(M20-M19)/M19 -> -0.018077325
A21: 44224 | B21: 228.74074 | C21: =YEAR(A21) -> 2021 | D21: =MONTH(A21) -> 1 | E21: =_xlfn.ISOWEEKNUM(A21) -> 4 | F21: =WEEKDAY(A21,2) -> 4 | G21: =_xlfn.MINIFS($A$4:$A$1346,$C$4:$C$1346,C21,$D$4:$D$1346,D21) -> 44200 | H21: =_xlfn.MAXIFS($A$4:$A$1346,$C$4:$C$1346,C21,$D$4:$D$1346,D21) -> 44225 | J21: 44713 | K21: 44742 | L21: =INDEX($B$4:$B$1346,MATCH(J21,$A$4:$A$1346)) -> 264.1463 | M21: =INDEX($B$4:$B$1346,MATCH(K21,$A$4:$A$1346)) -> 249.02975 | N21: =(M21-M20)/M20 -> -0.055320575
A22: 44225 | B22: 222.06799 | C22: =YEAR(A22) -> 2021 | D22: =MONTH(A22) -> 1 | E22: =_xlfn.ISOWEEKNUM(A22) -> 4 | F22: =WEEKDAY(A22,2) -> 5 | G22: =_xlfn.MINIFS($A$4:$A$1346,$C$4:$C$1346,C22,$D$4:$D$1346,D22) -> 44200 | H22: =_xlfn.MAXIFS($A$4:$A$1346,$C$4:$C$1346,C22,$D$4:$D$1346,D22) -> 44225 | J22: 44743 | K22: 44771 | L22: =INDEX($B$4:$B$1346,MATCH(J22,$A$4:$A$1346)) -> 251.69621 | M22: =INDEX($B$4:$B$1346,MATCH(K22,$A$4:$A$1346)) -> 272.21359 | N22: =(M22-M21)/M21 -> 0.093096658
A23: 44228 | B23: 229.43005 | C23: =YEAR(A23) -> 2021 | D23: =MONTH(A23) -> 2 | E23: =_xlfn.ISOWEEKNUM(A23) -> 5 | F23: =WEEKDAY(A23,2) -> 1 | G23: =_xlfn.MINIFS($A$4:$A$1346,$C$4:$C$1346,C23,$D$4:$D$1346,D23) -> 44228 | H23: =_xlfn.MAXIFS($A$4:$A$1346,$C$4:$C$1346,C23,$D$4:$D$1346,D23) -> 44253 | J23: 44774 | K23: 44804 | L23: =INDEX($B$4:$B$1346,MATCH(J23,$A$4:$A$1346)) -> 269.56653 | M23: =INDEX($B$4:$B$1346,MATCH(K23,$A$4:$A$1346)) -> 254.06694 | N23: =(M23-M22)/M22 -> -0.066663285
A24: 44229 | B24: 229.29599 | C24: =YEAR(A24) -> 2021 | D24: =MONTH(A24) -> 2 | E24: =_xlfn.ISOWEEKNUM(A24) -> 5 | F24: =WEEKDAY(A24,2) -> 2 | G24: =_xlfn.MINIFS($A$4:$A$1346,$C$4:$C$1346,C24,$D$4:$D$1346,D24) -> 44228 | H24: =_xlfn.MAXIFS($A$4:$A$1346,$C$4:$C$1346,C24,$D$4:$D$1346,D24) -> 44253 | J24: 44805 | K24: 44834 | L24: =INDEX($B$4:$B$1346,MATCH(J24,$A$4:$A$1346)) -> 253.02727 | M24: =INDEX($B$4:$B$1346,MATCH(K24,$A$4:$A$1346)) -> 226.30586 | N24: =(M24-M23)/M23 -> -0.10926679
A25: 44230 | B25: 232.63716 | C25: =YEAR(A25) -> 2021 | D25: =MONTH(A25) -> 2 | E25: =_xlfn.ISOWEEKNUM(A25) -> 5 | F25: =WEEKDAY(A25,2) -> 3 | G25: =_xlfn.MINIFS($A$4:$A$1346,$C$4:$C$1346,C25,$D$4:$D$1346,D25) -> 44228 | H25: =_xlfn.MAXIFS($A$4:$A$1346,$C$4:$C$1346,C25,$D$4:$D$1346,D25) -> 44253 | J25: 44837 | K25: 44865 | L25: =INDEX($B$4:$B$1346,MATCH(J25,$A$4:$A$1346)) -> 233.92389 | M25: =INDEX($B$4:$B$1346,MATCH(K25,$A$4:$A$1346)) -> 225.55766 | N25: =(M25-M24)/M24 -> -0.0033061426
A26: 44231 | B26: 231.68939 | C26: =YEAR(A26) -> 2021 | D26: =MONTH(A26) -> 2 | E26: =_xlfn.ISOWEEKNUM(A26) -> 5 | F26: =WEEKDAY(A26,2) -> 4 | G26: =_xlfn.MINIFS($A$4:$A$1346,$C$4:$C$1346,C26,$D$4:$D$1346,D26) -> 44228 | H26: =_xlfn.MAXIFS($A$4:$A$1346,$C$4:$C$1346,C26,$D$4:$D$1346,D26) -> 44253 | J26: 44866 | K26: 44895 | L26: =INDEX($B$4:$B$1346,MATCH(J26,$A$4:$A$1346)) -> 221.70981 | M26: =INDEX($B$4:$B$1346,MATCH(K26,$A$4:$A$1346)) -> 248.61484 | N26: =(M26-M25)/M25 -> 0.10222297
A27: 44232 | B27: 231.87132 | C27: =YEAR(A27) -> 2021 | D27: =MONTH(A27) -> 2 | E27: =_xlfn.ISOWEEKNUM(A27) -> 5 | F27: =WEEKDAY(A27,2) -> 5 | G27: =_xlfn.MINIFS($A$4:$A$1346,$C$4:$C$1346,C27,$D$4:$D$1346,D27) -> 44228 | H27: =_xlfn.MAXIFS($A$4:$A$1346,$C$4:$C$1346,C27,$D$4:$D$1346,D27) -> 44253 | J27: 44896 | K27: 44925 | L27: =INDEX($B$4:$B$1346,MATCH(J27,$A$4:$A$1346)) -> 248.17636 | M27: =INDEX($B$4:$B$1346,MATCH(K27,$A$4:$A$1346)) -> 233.68668 | N27: =(M27-M26)/M26 -> -0.060045337
A28: 44235 | B28: 232.12979 | C28: =YEAR(A28) -> 2021 | D28: =MONTH(A28) -> 2 | E28: =_xlfn.ISOWEEKNUM(A28) -> 6 | F28: =WEEKDAY(A28,2) -> 1 | G28: =_xlfn.MINIFS($A$4:$A$1346,$C$4:$C$1346,C28,$D$4:$D$1346,D28) -> 44228 | H28: =_xlfn.MAXIFS($A$4:$A$1346,$C$4:$C$1346,C28,$D$4:$D$1346,D28) -> 44253 | J28: 44929 | K28: 44957 | L28: =INDEX($B$4:$B$1346,MATCH(J28,$A$4:$A$1346)) -> 233.4528 | M28: =INDEX($B$4:$B$1346,MATCH(K28,$A$4:$A$1346)) -> 241.47234 | N28: =(M28-M27)/M27 -> 0.033316661
A29: 44236 | B29: 233.37436 | C29: =YEAR(A29) -> 2021 | D29: =MONTH(A29) -> 2 | E29: =_xlfn.ISOWEEKNUM(A29) -> 6 | F29: =WEEKDAY(A29,2) -> 2 | G29: =_xlfn.MINIFS($A$4:$A$1346,$C$4:$C$1346,C29,$D$4:$D$1346,D29) -> 44228 | H29: =_xlfn.MAXIFS($A$4:$A$1346,$C$4:$C$1346,C29,$D$4:$D$1346,D29) -> 44253 | J29: 44958 | K29: 44985 | L29: =INDEX($B$4:$B$1346,MATCH(J29,$A$4:$A$1346)) -> 246.28598 | M29: =INDEX($B$4:$B$1346,MATCH(K29,$A$4:$A$1346)) -> 243.64987 | N29: =(M29-M28)/M28 -> 0.0090177453
A30: 44237 | B30: 232.46487 | C30: =YEAR(A30) -> 2021 | D30: =MONTH(A30) -> 2 | E30: =_xlfn.ISOWEEKNUM(A30) -> 6 | F30: =WEEKDAY(A30,2) -> 3 | G30: =_xlfn.MINIFS($A$4:$A$1346,$C$4:$C$1346,C30,$D$4:$D$1346,D30) -> 44228 | H30: =_xlfn.MAXIFS($A$4:$A$1346,$C$4:$C$1346,C30,$D$4:$D$1346,D30) -> 44253 | J30: 44986 | K30: 45016 | L30: =INDEX($B$4:$B$1346,MATCH(J30,$A$4:$A$1346)) -> 240.57277 | M30: =INDEX($B$4:$B$1346,MATCH(K30,$A$4:$A$1346)) -> 281.63037 | N30: =(M30-M29)/M29 -> 0.15588147
A31: 44238 | B31: 234.06361 | C31: =YEAR(A31) -> 2021 | D31: =MONTH(A31) -> 2 | E31: =_xlfn.ISOWEEKNUM(A31) -> 6 | F31: =WEEKDAY(A31,2) -> 4 | G31: =_xlfn.MINIFS($A$4:$A$1346,$C$4:$C$1346,C31,$D$4:$D$1346,D31) -> 44228 | H31: =_xlfn.MAXIFS($A$4:$A$1346,$C$4:$C$1346,C31,$D$4:$D$1346,D31) -> 44253 | J31: 45019 | K31: 45044 | L31: =INDEX($B$4:$B$1346,MATCH(J31,$A$4:$A$1346)) -> 280.58524 | M31: =INDEX($B$4:$B$1346,MATCH(K31,$A$4:$A$1346)) -> 300.15182 | N31: =(M31-M30)/M30 -> 0.065765115
... A68: 44293 | B68: 239.79398 | C68: =YEAR(A68) -> 2021 | D68: =MONTH(A68) -> 4 | E68: =_xlfn.ISOWEEKNUM(A68) -> 14 | F68: =WEEKDAY(A68,2) -> 3 | G68: =_xlfn.MINIFS($A$4:$A$1346,$C$4:$C$1346,C68,$D$4:$D$1346,D68) -> 44287 | H68: =_xlfn.MAXIFS($A$4:$A$1346,$C$4:$C$1346,C68,$D$4:$D$1346,D68) -> 44316 | J68: 46143 | K68: 46150 | L68: =INDEX($B$4:$B$1346,MATCH(J68,$A$4:$A$1346)) -> 414.44 | M68: =INDEX($B$4:$B$1346,MATCH(K68,$A$4:$A$1346)) -> 415.12 | N68: =(M68-M67)/M67 -> 0.017999893
A69: 44294 | B69: 243.00847 | C69: =YEAR(A69) -> 2021 | D69: =MONTH(A69) -> 4 | E69: =_xlfn.ISOWEEKNUM(A69) -> 14 | F69: =WEEKDAY(A69,2) -> 4 | G69: =_xlfn.MINIFS($A$4:$A$1346,$C$4:$C$1346,C69,$D$4:$D$1346,D69) -> 44287 | H69: =_xlfn.MAXIFS($A$4:$A$1346,$C$4:$C$1346,C69,$D$4:$D$1346,D69) -> 44316
A70: 44295 | B70: 245.50334 | C70: =YEAR(A70) -> 2021 | D70: =MONTH(A70) -> 4 | E70: =_xlfn.ISOWEEKNUM(A70) -> 14 | F70: =WEEKDAY(A70,2) -> 5 | G70: =_xlfn.MINIFS($A$4:$A$1346,$C$4:$C$1346,C70,$D$4:$D$1346,D70) -> 44287 | H70: =_xlfn.MAXIFS($A$4:$A$1346,$C$4:$C$1346,C70,$D$4:$D$1346,D70) -> 44316
A71: 44298 | B71: 245.5609 | C71: =YEAR(A71) -> 2021 | D71: =MONTH(A71) -> 4 | E71: =_xlfn.ISOWEEKNUM(A71) -> 15 | F71: =WEEKDAY(A71,2) -> 1 | G71: =_xlfn.MINIFS($A$4:$A$1346,$C$4:$C$1346,C71,$D$4:$D$1346,D71) -> 44287 | H71: =_xlfn.MAXIFS($A$4:$A$1346,$C$4:$C$1346,C71,$D$4:$D$1346,D71) -> 44316
A72: 44299 | B72: 248.03654 | C72: =YEAR(A72) -> 2021 | D72: =MONTH(A72) -> 4 | E72: =_xlfn.ISOWEEKNUM(A72) -> 15 | F72: =WEEKDAY(A72,2) -> 2 | G72: =_xlfn.MINIFS($A$4:$A$1346,$C$4:$C$1346,C72,$D$4:$D$1346,D72) -> 44287 | H72: =_xlfn.MAXIFS($A$4:$A$1346,$C$4:$C$1346,C72,$D$4:$D$1346,D72) -> 44316
A73: 44300 | B73: 245.25381 | C73: =YEAR(A73) -> 2021 | D73: =MONTH(A73) -> 4 | E73: =_xlfn.ISOWEEKNUM(A73) -> 15 | F73: =WEEKDAY(A73,2) -> 3 | G73: =_xlfn.MINIFS($A$4:$A$1346,$C$4:$C$1346,C73,$D$4:$D$1346,D73) -> 44287 | H73: =_xlfn.MAXIFS($A$4:$A$1346,$C$4:$C$1346,C73,$D$4:$D$1346,D73) -> 44316
A74: 44301 | B74: 249.00571 | C74: =YEAR(A74) -> 2021 | D74: =MONTH(A74) -> 4 | E74: =_xlfn.ISOWEEKNUM(A74) -> 15 | F74: =WEEKDAY(A74,2) -> 4 | G74: =_xlfn.MINIFS($A$4:$A$1346,$C$4:$C$1346,C74,$D$4:$D$1346,D74) -> 44287 | H74: =_xlfn.MAXIFS($A$4:$A$1346,$C$4:$C$1346,C74,$D$4:$D$1346,D74) -> 44316
A75: 44302 | B75: 250.19553 | C75: =YEAR(A75) -> 2021 | D75: =MONTH(A75) -> 4 | E75: =_xlfn.ISOWEEKNUM(A75) -> 15 | F75: =WEEKDAY(A75,2) -> 5 | G75: =_xlfn.MINIFS($A$4:$A$1346,$C$4:$C$1346,C75,$D$4:$D$1346,D75) -> 44287 | H75: =_xlfn.MAXIFS($A$4:$A$1346,$C$4:$C$1346,C75,$D$4:$D$1346,D75) -> 44316
A76: 44305 | B76: 248.27643 | C76: =YEAR(A76) -> 2021 | D76: =MONTH(A76) -> 4 | E76: =_xlfn.ISOWEEKNUM(A76) -> 16 | F76: =WEEKDAY(A76,2) -> 1 | G76: =_xlfn.MINIFS($A$4:$A$1346,$C$4:$C$1346,C76,$D$4:$D$1346,D76) -> 44287 | H76: =_xlfn.MAXIFS($A$4:$A$1346,$C$4:$C$1346,C76,$D$4:$D$1346,D76) -> 44316
A77: 44306 | B77: 247.81583 | C77: =YEAR(A77) -> 2021 | D77: =MONTH(A77) -> 4 | E77: =_xlfn.ISOWEEKNUM(A77) -> 16 | F77: =WEEKDAY(A77,2) -> 2 | G77: =_xlfn.MINIFS($A$4:$A$1346,$C$4:$C$1346,C77,$D$4:$D$1346,D77) -> 44287 | H77: =_xlfn.MAXIFS($A$4:$A$1346,$C$4:$C$1346,C77,$D$4:$D$1346,D77) -> 44316
...

Sheet Rend. Annuali MSFT
A1: RENDIMENTI ANNUALI DI MSFT
A3: Date | B3: Close | C3: Anno | D3: Mese | E3: Settimana ISO | F3: Giorno | G3: Data inizio anno | H3: Data fine anno | J3: Data inizio anno | K3: Data fine anno | L3: Prezzo chiusura inizio anno | M3: Prezzo chiusura fine anno | N3: Rendimenti annuali
A4: 44200 | B4: 208.40652 | C4: =YEAR(A4) -> 2021 | D4: =MONTH(A4) -> 1 | E4: =_xlfn.ISOWEEKNUM(A4) -> 1 | F4: =WEEKDAY(A4,2) -> 1 | G4: =_xlfn.MINIFS($A$4:$A$1346,$C$4:$C$1346,C4,$C$4:$C$1346,C4) -> 44200 | H4: =_xlfn.MAXIFS($A$4:$A$1346,$C$4:$C$1346,C4,$C$4:$C$1346,C4) -> 44561 | J4: {=_xlfn.UNIQUE(G4:G1346)} -> 44200 | K4: {=_xlfn.UNIQUE(H4:H1346)} -> 44561 | L4: =INDEX($B$4:$B$1346,MATCH(J4,$A$4:$A$1346)) -> 208.40652 | M4: =INDEX($B$4:$B$1346,MATCH(K4,$A$4:$A$1346)) -> 324.67642 | N4: 0
A5: 44201 | B5: 208.60757 | C5: =YEAR(A5) -> 2021 | D5: =MONTH(A5) -> 1 | E5: =_xlfn.ISOWEEKNUM(A5) -> 1 | F5: =WEEKDAY(A5,2) -> 2 | G5: =_xlfn.MINIFS($A$4:$A$1346,$C$4:$C$1346,C5,$C$4:$C$1346,C5) -> 44200 | H5: =_xlfn.MAXIFS($A$4:$A$1346,$C$4:$C$1346,C5,$C$4:$C$1346,C5) -> 44561 | J5: 44564 | K5: 44925 | L5: =INDEX($B$4:$B$1346,MATCH(J5,$A$4:$A$1346)) -> 323.16074 | M5: =INDEX($B$4:$B$1346,MATCH(K5,$A$4:$A$1346)) -> 233.68668 | N5: =(M5-M4)/M4 -> -0.28024747
A6: 44202 | B6: 203.19855 | C6: =YEAR(A6) -> 2021 | D6: =MONTH(A6) -> 1 | E6: =_xlfn.ISOWEEKNUM(A6) -> 1 | F6: =WEEKDAY(A6,2) -> 3 | G6: =_xlfn.MINIFS($A$4:$A$1346,$C$4:$C$1346,C6,$C$4:$C$1346,C6) -> 44200 | H6: =_xlfn.MAXIFS($A$4:$A$1346,$C$4:$C$1346,C6,$C$4:$C$1346,C6) -> 44561 | J6: 44929 | K6: 45289 | L6: =INDEX($B$4:$B$1346,MATCH(J6,$A$4:$A$1346)) -> 233.4528 | M6: =INDEX($B$4:$B$1346,MATCH(K6,$A$4:$A$1346)) -> 369.67194 | N6: =(M6-M5)/M5 -> 0.58191277
A7: 44203 | B7: 208.9809 | C7: =YEAR(A7) -> 2021 | D7: =MONTH(A7) -> 1 | E7: =_xlfn.ISOWEEKNUM(A7) -> 1 | F7: =WEEKDAY(A7,2) -> 4 | G7: =_xlfn.MINIFS($A$4:$A$1346,$C$4:$C$1346,C7,$C$4:$C$1346,C7) -> 44200 | H7: =_xlfn.MAXIFS($A$4:$A$1346,$C$4:$C$1346,C7,$C$4:$C$1346,C7) -> 44561 | J7: 45293 | K7: 45657 | L7: =INDEX($B$4:$B$1346,MATCH(J7,$A$4:$A$1346)) -> 364.58948 | M7: =INDEX($B$4:$B$1346,MATCH(K7,$A$4:$A$1346)) -> 417.46063 | N7: =(M7-M6)/M6 -> 0.12927326
A8: 44204 | B8: 210.25423 | C8: =YEAR(A8) -> 2021 | D8: =MONTH(A8) -> 1 | E8: =_xlfn.ISOWEEKNUM(A8) -> 1 | F8: =WEEKDAY(A8,2) -> 5 | G8: =_xlfn.MINIFS($A$4:$A$1346,$C$4:$C$1346,C8,$C$4:$C$1346,C8) -> 44200 | H8: =_xlfn.MAXIFS($A$4:$A$1346,$C$4:$C$1346,C8,$C$4:$C$1346,C8) -> 44561 | J8: 45659 | K8: 46022 | L8: =INDEX($B$4:$B$1346,MATCH(J8,$A$4:$A$1346)) -> 414.5686 | M8: =INDEX($B$4:$B$1346,MATCH(K8,$A$4:$A$1346)) -> 482.51868 | N8: =(M8-M7)/M7 -> 0.15584235
A9: 44207 | B9: 208.21504 | C9: =YEAR(A9) -> 2021 | D9: =MONTH(A9) -> 1 | E9: =_xlfn.ISOWEEKNUM(A9) -> 2 | F9: =WEEKDAY(A9,2) -> 1 | G9: =_xlfn.MINIFS($A$4:$A$1346,$C$4:$C$1346,C9,$C$4:$C$1346,C9) -> 44200 | H9: =_xlfn.MAXIFS($A$4:$A$1346,$C$4:$C$1346,C9,$C$4:$C$1346,C9) -> 44561 | J9: 46024 | K9: 46150 | L9: =INDEX($B$4:$B$1346,MATCH(J9,$A$4:$A$1346)) -> 471.86301 | M9: =INDEX($B$4:$B$1346,MATCH(K9,$A$4:$A$1346)) -> 415.12 | N9: =(M9-M8)/M8 -> -0.13968098
A10: 44208 | B10: 205.76424 | C10: =YEAR(A10) -> 2021 | D10: =MONTH(A10) -> 1 | E10: =_xlfn.ISOWEEKNUM(A10) -> 2 | F10: =WEEKDAY(A10,2) -> 2 | G10: =_xlfn.MINIFS($A$4:$A$1346,$C$4:$C$1346,C10,$C$4:$C$1346,C10) -> 44200 | H10: =_xlfn.MAXIFS($A$4:$A$1346,$C$4:$C$1346,C10,$C$4:$C$1346,C10) -> 44561
A11: 44209 | B11: 207.11411 | C11: =YEAR(A11) -> 2021 | D11: =MONTH(A11) -> 1 | E11: =_xlfn.ISOWEEKNUM(A11) -> 2 | F11: =WEEKDAY(A11,2) -> 3 | G11: =_xlfn.MINIFS($A$4:$A$1346,$C$4:$C$1346,C11,$C$4:$C$1346,C11) -> 44200 | H11: =_xlfn.MAXIFS($A$4:$A$1346,$C$4:$C$1346,C11,$C$4:$C$1346,C11) -> 44561
A12: 44210 | B12: 203.9357 | C12: =YEAR(A12) -> 2021 | D12: =MONTH(A12) -> 1 | E12: =_xlfn.ISOWEEKNUM(A12) -> 2 | F12: =WEEKDAY(A12,2) -> 4 | G12: =_xlfn.MINIFS($A$4:$A$1346,$C$4:$C$1346,C12,$C$4:$C$1346,C12) -> 44200 | H12: =_xlfn.MAXIFS($A$4:$A$1346,$C$4:$C$1346,C12,$C$4:$C$1346,C12) -> 44561 | L12: Statistiche rendimenti annuali MSFT
A13: 44211 | B13: 203.58147 | C13: =YEAR(A13) -> 2021 | D13: =MONTH(A13) -> 1 | E13: =_xlfn.ISOWEEKNUM(A13) -> 2 | F13: =WEEKDAY(A13,2) -> 5 | G13: =_xlfn.MINIFS($A$4:$A$1346,$C$4:$C$1346,C13,$C$4:$C$1346,C13) -> 44200 | H13: =_xlfn.MAXIFS($A$4:$A$1346,$C$4:$C$1346,C13,$C$4:$C$1346,C13) -> 44561
A14: 44215 | B14: 207.20987 | C14: =YEAR(A14) -> 2021 | D14: =MONTH(A14) -> 1 | E14: =_xlfn.ISOWEEKNUM(A14) -> 3 | F14: =WEEKDAY(A14,2) -> 2 | G14: =_xlfn.MINIFS($A$4:$A$1346,$C$4:$C$1346,C14,$C$4:$C$1346,C14) -> 44200 | H14: =_xlfn.MAXIFS($A$4:$A$1346,$C$4:$C$1346,C14,$C$4:$C$1346,C14) -> 44561 | L14: Media | M14: 0.089419984
A15: 44216 | B15: 214.77293 | C15: =YEAR(A15) -> 2021 | D15: =MONTH(A15) -> 1 | E15: =_xlfn.ISOWEEKNUM(A15) -> 3 | F15: =WEEKDAY(A15,2) -> 3 | G15: =_xlfn.MINIFS($A$4:$A$1346,$C$4:$C$1346,C15,$C$4:$C$1346,C15) -> 44200 | H15: =_xlfn.MAXIFS($A$4:$A$1346,$C$4:$C$1346,C15,$C$4:$C$1346,C15) -> 44561 | L15: Errore standard | M15: 0.14793421
A16: 44217 | B16: 215.37611 | C16: =YEAR(A16) -> 2021 | D16: =MONTH(A16) -> 1 | E16: =_xlfn.ISOWEEKNUM(A16) -> 3 | F16: =WEEKDAY(A16,2) -> 4 | G16: =_xlfn.MINIFS($A$4:$A$1346,$C$4:$C$1346,C16,$C$4:$C$1346,C16) -> 44200 | H16: =_xlfn.MAXIFS($A$4:$A$1346,$C$4:$C$1346,C16,$C$4:$C$1346,C16) -> 44561 | L16: Mediana | M16: 0.12927326
A17: 44218 | B17: 216.31425 | C17: =YEAR(A17) -> 2021 | D17: =MONTH(A17) -> 1 | E17: =_xlfn.ISOWEEKNUM(A17) -> 3 | F17: =WEEKDAY(A17,2) -> 5 | G17: =_xlfn.MINIFS($A$4:$A$1346,$C$4:$C$1346,C17,$C$4:$C$1346,C17) -> 44200 | H17: =_xlfn.MAXIFS($A$4:$A$1346,$C$4:$C$1346,C17,$C$4:$C$1346,C17) -> 44561 | L17: Moda | M17: #N/A
A18: 44221 | B18: 219.74161 | C18: =YEAR(A18) -> 2021 | D18: =MONTH(A18) -> 1 | E18: =_xlfn.ISOWEEKNUM(A18) -> 4 | F18: =WEEKDAY(A18,2) -> 1 | G18: =_xlfn.MINIFS($A$4:$A$1346,$C$4:$C$1346,C18,$C$4:$C$1346,C18) -> 44200 | H18: =_xlfn.MAXIFS($A$4:$A$1346,$C$4:$C$1346,C18,$C$4:$C$1346,C18) -> 44561 | L18: Deviazione standard | M18: 0.33079096
A19: 44222 | B19: 222.42221 | C19: =YEAR(A19) -> 2021 | D19: =MONTH(A19) -> 1 | E19: =_xlfn.ISOWEEKNUM(A19) -> 4 | F19: =WEEKDAY(A19,2) -> 2 | G19: =_xlfn.MINIFS($A$4:$A$1346,$C$4:$C$1346,C19,$C$4:$C$1346,C19) -> 44200 | H19: =_xlfn.MAXIFS($A$4:$A$1346,$C$4:$C$1346,C19,$C$4:$C$1346,C19) -> 44561 | L19: Varianza campionaria | M19: 0.10942266
A20: 44223 | B20: 222.96788 | C20: =YEAR(A20) -> 2021 | D20: =MONTH(A20) -> 1 | E20: =_xlfn.ISOWEEKNUM(A20) -> 4 | F20: =WEEKDAY(A20,2) -> 3 | G20: =_xlfn.MINIFS($A$4:$A$1346,$C$4:$C$1346,C20,$C$4:$C$1346,C20) -> 44200 | H20: =_xlfn.MAXIFS($A$4:$A$1346,$C$4:$C$1346,C20,$C$4:$C$1346,C20) -> 44561 | L20: Curtosi | M20: 0.3812719
A21: 44224 | B21: 228.74074 | C21: =YEAR(A21) -> 2021 | D21: =MONTH(A21) -> 1 | E21: =_xlfn.ISOWEEKNUM(A21) -> 4 | F21: =WEEKDAY(A21,2) -> 4 | G21: =_xlfn.MINIFS($A$4:$A$1346,$C$4:$C$1346,C21,$C$4:$C$1346,C21) -> 44200 | H21: =_xlfn.MAXIFS($A$4:$A$1346,$C$4:$C$1346,C21,$C$4:$C$1346,C21) -> 44561 | L21: Asimmetria | M21: 0.65924161
A22: 44225 | B22: 222.06799 | C22: =YEAR(A22) -> 2021 | D22: =MONTH(A22) -> 1 | E22: =_xlfn.ISOWEEKNUM(A22) -> 4 | F22: =WEEKDAY(A22,2) -> 5 | G22: =_xlfn.MINIFS($A$4:$A$1346,$C$4:$C$1346,C22,$C$4:$C$1346,C22) -> 44200 | H22: =_xlfn.MAXIFS($A$4:$A$1346,$C$4:$C$1346,C22,$C$4:$C$1346,C22) -> 44561 | L22: Intervallo | M22: 0.86216024
A23: 44228 | B23: 229.43005 | C23: =YEAR(A23) -> 2021 | D23: =MONTH(A23) -> 2 | E23: =_xlfn.ISOWEEKNUM(A23) -> 5 | F23: =WEEKDAY(A23,2) -> 1 | G23: =_xlfn.MINIFS($A$4:$A$1346,$C$4:$C$1346,C23,$C$4:$C$1346,C23) -> 44200 | H23: =_xlfn.MAXIFS($A$4:$A$1346,$C$4:$C$1346,C23,$C$4:$C$1346,C23) -> 44561 | L23: Minimo | M23: -0.28024747
A24: 44229 | B24: 229.29599 | C24: =YEAR(A24) -> 2021 | D24: =MONTH(A24) -> 2 | E24: =_xlfn.ISOWEEKNUM(A24) -> 5 | F24: =WEEKDAY(A24,2) -> 2 | G24: =_xlfn.MINIFS($A$4:$A$1346,$C$4:$C$1346,C24,$C$4:$C$1346,C24) -> 44200 | H24: =_xlfn.MAXIFS($A$4:$A$1346,$C$4:$C$1346,C24,$C$4:$C$1346,C24) -> 44561 | L24: Massimo | M24: 0.58191277
A25: 44230 | B25: 232.63716 | C25: =YEAR(A25) -> 2021 | D25: =MONTH(A25) -> 2 | E25: =_xlfn.ISOWEEKNUM(A25) -> 5 | F25: =WEEKDAY(A25,2) -> 3 | G25: =_xlfn.MINIFS($A$4:$A$1346,$C$4:$C$1346,C25,$C$4:$C$1346,C25) -> 44200 | H25: =_xlfn.MAXIFS($A$4:$A$1346,$C$4:$C$1346,C25,$C$4:$C$1346,C25) -> 44561 | L25: Somma | M25: 0.44709992
A26: 44231 | B26: 231.68939 | C26: =YEAR(A26) -> 2021 | D26: =MONTH(A26) -> 2 | E26: =_xlfn.ISOWEEKNUM(A26) -> 5 | F26: =WEEKDAY(A26,2) -> 4 | G26: =_xlfn.MINIFS($A$4:$A$1346,$C$4:$C$1346,C26,$C$4:$C$1346,C26) -> 44200 | H26: =_xlfn.MAXIFS($A$4:$A$1346,$C$4:$C$1346,C26,$C$4:$C$1346,C26) -> 44561 | L26: Conteggio | M26: 5
A27: 44232 | B27: 231.87132 | C27: =YEAR(A27) -> 2021 | D27: =MONTH(A27) -> 2 | E27: =_xlfn.ISOWEEKNUM(A27) -> 5 | F27: =WEEKDAY(A27,2) -> 5 | G27: =_xlfn.MINIFS($A$4:$A$1346,$C$4:$C$1346,C27,$C$4:$C$1346,C27) -> 44200 | H27: =_xlfn.MAXIFS($A$4:$A$1346,$C$4:$C$1346,C27,$C$4:$C$1346,C27) -> 44561 | L27: Livello di confidenza(95,0%) | M27: 0.41073122
A28: 44235 | B28: 232.12979 | C28: =YEAR(A28) -> 2021 | D28: =MONTH(A28) -> 2 | E28: =_xlfn.ISOWEEKNUM(A28) -> 6 | F28: =WEEKDAY(A28,2) -> 1 | G28: =_xlfn.MINIFS($A$4:$A$1346,$C$4:$C$1346,C28,$C$4:$C$1346,C28) -> 44200 | H28: =_xlfn.MAXIFS($A$4:$A$1346,$C$4:$C$1346,C28,$C$4:$C$1346,C28) -> 44561
A29: 44236 | B29: 233.37436 | C29: =YEAR(A29) -> 2021 | D29: =MONTH(A29) -> 2 | E29: =_xlfn.ISOWEEKNUM(A29) -> 6 | F29: =WEEKDAY(A29,2) -> 2 | G29: =_xlfn.MINIFS($A$4:$A$1346,$C$4:$C$1346,C29,$C$4:$C$1346,C29) -> 44200 | H29: =_xlfn.MAXIFS($A$4:$A$1346,$C$4:$C$1346,C29,$C$4:$C$1346,C29) -> 44561
A30: 44237 | B30: 232.46487 | C30: =YEAR(A30) -> 2021 | D30: =MONTH(A30) -> 2 | E30: =_xlfn.ISOWEEKNUM(A30) -> 6 | F30: =WEEKDAY(A30,2) -> 3 | G30: =_xlfn.MINIFS($A$4:$A$1346,$C$4:$C$1346,C30,$C$4:$C$1346,C30) -> 44200 | H30: =_xlfn.MAXIFS($A$4:$A$1346,$C$4:$C$1346,C30,$C$4:$C$1346,C30) -> 44561
A31: 44238 | B31: 234.06361 | C31: =YEAR(A31) -> 2021 | D31: =MONTH(A31) -> 2 | E31: =_xlfn.ISOWEEKNUM(A31) -> 6 | F31: =WEEKDAY(A31,2) -> 4 | G31: =_xlfn.MINIFS($A$4:$A$1346,$C$4:$C$1346,C31,$C$4:$C$1346,C31) -> 44200 | H31: =_xlfn.MAXIFS($A$4:$A$1346,$C$4:$C$1346,C31,$C$4:$C$1346,C31) -> 44561
A32: 44239 | B32: 234.5423 | C32: =YEAR(A32) -> 2021 | D32: =MONTH(A32) -> 2 | E32: =_xlfn.ISOWEEKNUM(A32) -> 6 | F32: =WEEKDAY(A32,2) -> 5 | G32: =_xlfn.MINIFS($A$4:$A$1346,$C$4:$C$1346,C32,$C$4:$C$1346,C32) -> 44200 | H32: =_xlfn.MAXIFS($A$4:$A$1346,$C$4:$C$1346,C32,$C$4:$C$1346,C32) -> 44561
A33: 44243 | B33: 233.30728 | C33: =YEAR(A33) -> 2021 | D33: =MONTH(A33) -> 2 | E33: =_xlfn.ISOWEEKNUM(A33) -> 7 | F33: =WEEKDAY(A33,2) -> 2 | G33: =_xlfn.MINIFS($A$4:$A$1346,$C$4:$C$1346,C33,$C$4:$C$1346,C33) -> 44200 | H33: =_xlfn.MAXIFS($A$4:$A$1346,$C$4:$C$1346,C33,$C$4:$C$1346,C33) -> 44561
A34: 44244 | B34: 234.32445 | C34: =YEAR(A34) -> 2021 | D34: =MONTH(A34) -> 2 | E34: =_xlfn.ISOWEEKNUM(A34) -> 7 | F34: =WEEKDAY(A34,2) -> 3 | G34: =_xlfn.MINIFS($A$4:$A$1346,$C$4:$C$1346,C34,$C$4:$C$1346,C34) -> 44200 | H34: =_xlfn.MAXIFS($A$4:$A$1346,$C$4:$C$1346,C34,$C$4:$C$1346,C34) -> 44561
A35: 44245 | B35: 233.93102 | C35: =YEAR(A35) -> 2021 | D35: =MONTH(A35) -> 2 | E35: =_xlfn.ISOWEEKNUM(A35) -> 7 | F35: =WEEKDAY(A35,2) -> 4 | G35: =_xlfn.MINIFS($A$4:$A$1346,$C$4:$C$1346,C35,$C$4:$C$1346,C35) -> 44200 | H35: =_xlfn.MAXIFS($A$4:$A$1346,$C$4:$C$1346,C35,$C$4:$C$1346,C35) -> 44561
A36: 44246 | B36: 231.22508 | C36: =YEAR(A36) -> 2021 | D36: =MONTH(A36) -> 2 | E36: =_xlfn.ISOWEEKNUM(A36) -> 7 | F36: =WEEKDAY(A36,2) -> 5 | G36: =_xlfn.MINIFS($A$4:$A$1346,$C$4:$C$1346,C36,$C$4:$C$1346,C36) -> 44200 | H36: =_xlfn.MAXIFS($A$4:$A$1346,$C$4:$C$1346,C36,$C$4:$C$1346,C36) -> 44561
A37: 44249 | B37: 225.02629 | C37: =YEAR(A37) -> 2021 | D37: =MONTH(A37) -> 2 | E37: =_xlfn.ISOWEEKNUM(A37) -> 8 | F37: =WEEKDAY(A37,2) -> 1 | G37: =_xlfn.MINIFS($A$4:$A$1346,$C$4:$C$1346,C37,$C$4:$C$1346,C37) -> 44200 | H37: =_xlfn.MAXIFS($A$4:$A$1346,$C$4:$C$1346,C37,$C$4:$C$1346,C37) -> 44561
A38: 44250 | B38: 223.83646 | C38: =YEAR(A38) -> 2021 | D38: =MONTH(A38) -> 2 | E38: =_xlfn.ISOWEEKNUM(A38) -> 8 | F38: =WEEKDAY(A38,2) -> 2 | G38: =_xlfn.MINIFS($A$4:$A$1346,$C$4:$C$1346,C38,$C$4:$C$1346,C38) -> 44200 | H38: =_xlfn.MAXIFS($A$4:$A$1346,$C$4:$C$1346,C38,$C$4:$C$1346,C38) -> 44561
A39: 44251 | B39: 225.06471 | C39: =YEAR(A39) -> 2021 | D39: =MONTH(A39) -> 2 | E39: =_xlfn.ISOWEEKNUM(A39) -> 8 | F39: =WEEKDAY(A39,2) -> 3 | G39: =_xlfn.MINIFS($A$4:$A$1346,$C$4:$C$1346,C39,$C$4:$C$1346,C39) -> 44200 | H39: =_xlfn.MAXIFS($A$4:$A$1346,$C$4:$C$1346,C39,$C$4:$C$1346,C39) -> 44561
... A1346: 46150 | B1346: 415.12 | C1346: =YEAR(A1346) -> 2026 | D1346: =MONTH(A1346) -> 5 | E1346: =_xlfn.ISOWEEKNUM(A1346) -> 19 | F1346: =WEEKDAY(A1346,2) -> 5 | G1346: =_xlfn.MINIFS($A$4:$A$1346,$C$4:$C$1346,C1346,$C$4:$C$1346,C1346) -> 46024 | H1346: =_xlfn.MAXIFS($A$4:$A$1346,$C$4:$C$1346,C1346,$C$4:$C$1346,C1346) -> 46150

Sheet Rend. GG SP500
A1: RENDIMENTI GIORNALIERI DI S&P 500
A3: Date | B3: Close | C3: Rendimenti giornalieri S&P500
A4: 44200 | B4: 3700.6499 | C4: 0 | F4: Statistiche rendimennti gg S&P500
A5: 44201 | B5: 3726.8601 | C5: =(B5-B4)/B4 -> 0.0070825952
A6: 44202 | B6: 3748.1399 | C6: =(B6-B5)/B5 -> 0.0057098427 | F6: Media | G6: 0.00057217816
A7: 44203 | B7: 3803.79 | C7: =(B7-B6)/B6 -> 0.014847404 | F7: Errore standard | G7: 0.00028857703
A8: 44204 | B8: 3824.6799 | C8: =(B8-B7)/B7 -> 0.0054918627 | F8: Mediana | G8: 0.0008197029
A9: 44207 | B9: 3799.6101 | C9: =(B9-B8)/B8 -> -0.0065547509 | F9: Moda | G9: #N/A
A10: 44208 | B10: 3801.1899 | C10: =(B10-B9)/B9 -> 0.00041578845 | F10: Deviazione standard | G10: 0.010571534
A11: 44209 | B11: 3809.8401 | C11: =(B11-B10)/B10 -> 0.0022756417 | F11: Varianza campionaria | G11: 0.00011175734
A12: 44210 | B12: 3795.54 | C12: =(B12-B11)/B11 -> -0.0037534512 | F12: Curtosi | G12: 6.9456446
A13: 44211 | B13: 3768.25 | C13: =(B13-B12)/B12 -> -0.007190028 | F13: Asimmetria | G13: 0.13554978
A14: 44215 | B14: 3798.9099 | C14: =(B14-B13)/B13 -> 0.0081363795 | F14: Intervallo | G14: 0.15490348
A15: 44216 | B15: 3851.8501 | C15: =(B15-B14)/B14 -> 0.013935625 | F15: Minimo | G15: -0.059749605
A16: 44217 | B16: 3853.0701 | C16: =(B16-B15)/B15 -> 0.00031672331 | F16: Massimo | G16: 0.095153876
A17: 44218 | B17: 3841.47 | C17: =(B17-B16)/B16 -> -0.0030106117 | F17: Somma | G17: 0.76786309
A18: 44221 | B18: 3855.3601 | C18: =(B18-B17)/B17 -> 0.0036158389 | F18: Conteggio | G18: 1342
A19: 44222 | B19: 3849.6201 | C19: =(B19-B18)/B18 -> -0.0014888337 | F19: Livello di confidenza(95,0%) | G19: 0.00056611155
A20: 44223 | B20: 3750.77 | C20: =(B20-B19)/B19 -> -0.025677884
A21: 44224 | B21: 3787.3799 | C21: =(B21-B20)/B20 -> 0.009760626
A22: 44225 | B22: 3714.24 | C22: =(B22-B21)/B21 -> -0.019311475
A23: 44228 | B23: 3773.8601 | C23: =(B23-B22)/B22 -> 0.016051768
A24: 44229 | B24: 3826.3101 | C24: =(B24-B23)/B23 -> 0.013898223
A25: 44230 | B25: 3830.1699 | C25: =(B25-B24)/B24 -> 0.0010087691
A26: 44231 | B26: 3871.74 | C26: =(B26-B25)/B25 -> 0.010853322
